Workbook

Sheet นครสวรรค์(2)
A1: บริษัท แวลู่พลัส รีเทล จำกัด | G1: รถคันที่ : | H1: 1/1
G2: วันที่ :
A3: ใบจัดสินค้า
A4: ลูกค้า | B4: บริษัท ซีพี ออลล์ จำกัด | D4: สถานที่จัดส่ง | F4: BDC.นครสวรรค์
A5: IV | D5: วันที่ส่ง | J5: คำวนตะกร้า
J6: ตะกร้าเต็ม | L6: ตะกร้าเศษ
A7: ลำดับ | B7: ชื่อสินค้า | C7: บรรจุ | D7: จำนวน | E7: หน่วย | F7: MFD | G7: BBF/EXP | H7: อายุคงเหลือ (วัน) | J7: ใบ | K7: ชิ้น | L7: ใบ | M7: ชิ้น | N7: เกณฑ์ | O7: คงเหลือวันที่ส่งได้
A8: 1 | B8: NEWยูมิยูมิ มิลค์เค้ก 55กรัม | C8: =SUMIF(Data!E:E,B8,Data!F:F) -> 42 | E8: ชิ้น | H8: =+G8-$D$6 -> 0 | J8: =ROUNDDOWN((D8/C8),0) -> 0 | K8: =SUMIF(Data!E:E,'มหาชัย(2)'!B8,Data!F:F)*J8 -> 0 | L8: =ROUNDUP((M8/C8),0) -> 0 | M8: =D8-K8 -> 0 | N8: =INDEX(Data!C:C,MATCH(F4,Data!B:B,0)) -> 60 | O8: =H8-N8 -> -60
A9: 2 | B9: ใหม่ !! ยูมิยูมิ เค้กไข่ชีส 78กรัม | C9: =SUMIF(Data!E:E,B9,Data!F:F) -> 36 | E9: ชิ้น | H9: =+G9-$D$6 -> 0 | J9: =ROUNDDOWN((D9/C9),0) -> 0 | K9: =SUMIF(Data!E:E,'มหาชัย(2)'!B9,Data!F:F)*J9 -> 0 | L9: =ROUNDUP((M9/C9),0) -> 0 | M9: =D9-K9 -> 0 | N9: =INDEX(Data!C:C,MATCH(F5,Data!B:B,0)) -> #N/A | O9: =H9-N9 -> #N/A
A10: 3 | B10: ยูมิยูมิ เค้กอัลมอนด์ 75กรัม | C10: =SUMIF(Data!E:E,B10,Data!F:F) -> 42 | E10: ชิ้น | H10: =+G10-$D$6 -> 0 | J10: =ROUNDDOWN((D10/C10),0) -> 0 | K10: =SUMIF(Data!E:E,'มหาชัย(2)'!B10,Data!F:F)*J10 -> 0 | L10: =ROUNDUP((M10/C10),0) -> 0 | M10: =D10-K10 -> 0 | N10: =INDEX(Data!C:C,MATCH(F6,Data!B:B,0)) -> #N/A | O10: =H10-N10 -> #N/A
A11: 4 | B11: ยูมิยูมิ โรลช็อกโกแลตเค้ก 55กรัม | C11: =SUMIF(Data!E:E,B11,Data!F:F) -> 50 | E11: ชิ้น | H11: =+G11-$D$6 -> 0 | J11: =ROUNDDOWN((D11/C11),0) -> 0 | K11: =SUMIF(Data!E:E,'มหาชัย(2)'!B11,Data!F:F)*J11 -> 0 | L11: =ROUNDUP((M11/C11),0) -> 0 | M11: =D11-K11 -> 0 | N11: =INDEX(Data!C:C,MATCH(F7,Data!B:B,0)) -> #N/A | O11: =H11-N11 -> #N/A
A12: 5 | B12: ยูมิยูมิ มินิครีมเค้ก 40กรัม | C12: =SUMIF(Data!E:E,B12,Data!F:F) -> 81 | E12: ชิ้น | H12: =+G12-$D$6 -> 0 | J12: =ROUNDDOWN((D12/C12),0) -> 0 | K12: =SUMIF(Data!E:E,'มหาชัย(2)'!B12,Data!F:F)*J12 -> 0 | L12: =ROUNDUP((M12/C12),0) -> 0 | M12: =D12-K12 -> 0 | N12: =INDEX(Data!C:C,MATCH(F8,Data!B:B,0)) -> #N/A | O12: =H12-N12 -> #N/A
A13: 6 | B13: ยูมิยูมิ เค้กครีมสลัดไก่หยอง 75กรัม | C13: =SUMIF(Data!E:E,B13,Data!F:F) -> 42 | E13: ชิ้น | H13: =+G13-$D$6 -> 0 | J13: =ROUNDDOWN((D13/C13),0) -> 0 | K13: =SUMIF(Data!E:E,'มหาชัย(2)'!B13,Data!F:F)*J13 -> 0 | L13: =ROUNDUP((M13/C13),0) -> 0 | M13: =D13-K13 -> 0 | N13: =INDEX(Data!C:C,MATCH(F9,Data!B:B,0)) -> #N/A | O13: =H13-N13 -> #N/A
A14: 7 | B14: ยูมิยูมิ ชิสึเค้ก 70กรัม | C14: =SUMIF(Data!E:E,B14,Data!F:F) -> 32 | E14: ชิ้น | H14: =+G14-$D$6 -> 0 | J14: =ROUNDDOWN((D14/C14),0) -> 0 | K14: =SUMIF(Data!E:E,'มหาชัย(2)'!B14,Data!F:F)*J14 -> 0 | L14: =ROUNDUP((M14/C14),0) -> 0 | M14: =D14-K14 -> 0 | N14: =INDEX(Data!C:C,MATCH(F10,Data!B:B,0)) -> #N/A | O14: =H14-N14 -> #N/A
A15: 8 | B15: ยูมิยูมิ บลูเบอร์รี่เค้ก 52กรัม | C15: =SUMIF(Data!E:E,B15,Data!F:F) -> 70 | E15: ชิ้น | H15: =+G15-$D$6 -> 0 | J15: =ROUNDDOWN((D15/C15),0) -> 0 | K15: =SUMIF(Data!E:E,'มหาชัย(2)'!B15,Data!F:F)*J15 -> 0 | L15: =ROUNDUP((M15/C15),0) -> 0 | M15: =D15-K15 -> 0 | N15: =INDEX(Data!C:C,MATCH(F11,Data!B:B,0)) -> #N/A | O15: =H15-N15 -> #N/A
A16: 9 | B16: ยูมิยูมิ เค้กสาหร่ายไก่หยอง 75กรัม | C16: =SUMIF(Data!E:E,B16,Data!F:F) -> 45 | E16: ชิ้น | H16: =+G16-$D$6 -> 0 | J16: =ROUNDDOWN((D16/C16),0) -> 0 | K16: =SUMIF(Data!E:E,'มหาชัย(2)'!B16,Data!F:F)*J16 -> 0 | L16: =ROUNDUP((M16/C16),0) -> 0 | M16: =D16-K16 -> 0 | N16: =INDEX(Data!C:C,MATCH(F12,Data!B:B,0)) -> #N/A | O16: =H16-N16 -> #N/A
A17: 10 | B17: ยูมิยูมิ เค้กช็อกโกแลตเฮเซลนัท 75กรัม | C17: =SUMIF(Data!E:E,B17,Data!F:F) -> 48 | E17: ชิ้น | H17: =+G17-$D$6 -> 0 | J17: =ROUNDDOWN((D17/C17),0) -> 0 | K17: =SUMIF(Data!E:E,'มหาชัย(2)'!B17,Data!F:F)*J17 -> 0 | L17: =ROUNDUP((M17/C17),0) -> 0 | M17: =D17-K17 -> 0 | N17: =INDEX(Data!C:C,MATCH(F13,Data!B:B,0)) -> #N/A | O17: =H17-N17 -> #N/A
A18: 11 | B18: ยูมิยูมิ ชิฟฟอนชีสเค้ก 75กรัม | C18: =SUMIF(Data!E:E,B18,Data!F:F) -> 48 | E18: ชิ้น | H18: =+G18-$D$6 -> 0 | J18: =ROUNDDOWN((D18/C18),0) -> 0 | K18: =SUMIF(Data!E:E,'มหาชัย(2)'!B18,Data!F:F)*J18 -> 0 | L18: =ROUNDUP((M18/C18),0) -> 0 | M18: =D18-K18 -> 0 | N18: =INDEX(Data!C:C,MATCH(F14,Data!B:B,0)) -> #N/A | O18: =H18-N18 -> #N/A
A19: 12 | B19: วาฟเฟิลครีมโคโคนัทมิลค์ 62กรัม | C19: =SUMIF(Data!E:E,B19,Data!F:F) -> 60 | E19: ชิ้น | H19: =+G19-$D$6 -> 0 | J19: =ROUNDDOWN((D19/C19),0) -> 0 | K19: =SUMIF(Data!E:E,'มหาชัย(2)'!B19,Data!F:F)*J19 -> 0 | L19: =ROUNDUP((M19/C19),0) -> 0 | M19: =D19-K19 -> 0 | N19: =INDEX(Data!C:C,MATCH(F15,Data!B:B,0)) -> #N/A | O19: =H19-N19 -> #N/A
... A26: 19 | B26: ยูมิยูมิ มินิเค้กไส้ครีมกล้วยหอม 40กรัม | C26: =SUMIF(Data!E:E,B26,Data!F:F) -> 81 | E26: ชิ้น | H26: =+G26-$D$6 -> 0 | J26: =ROUNDDOWN((D26/C26),0) -> 0 | K26: =SUMIF(Data!E:E,'มหาชัย(2)'!B26,Data!F:F)*J26 -> 0 | L26: =ROUNDUP((M26/C26),0) -> 0 | M26: =D26-K26 -> 0 | N26: =INDEX(Data!C:C,MATCH(F22,Data!B:B,0)) -> #N/A | O26: =H26-N26 -> #N/A
A27: ยอดรวมสินค้า | J27: ตะกร้าเต็ม | K27: ตะกร้าเศษ | L27: รวมตะกร้า
J28: =SUM($J$8:$J$26) -> 0 | K28: =SUM($L$8:$L$26) -> 0 | L28: =SUM(J28:K28) -> 0
B30: ผู้รับผิดชอบ.......................................... ผู้ตรวจ (เช็คเกอร์)....................................... | G30: พนักงานขนส่ง.......................................... | K30: ยอดตระกร้ารวม | L30: =SUM('นครสวรรค์(2):ขอนแก่น(1)'!L28) -> 0
B31: วันที่จัดเสร็จ.......................................... วันที่จัดเสร็จ................................................ | G31: ทะเบียนขนส่ง............................................. | K31: ใช้รถ | L31: =L30/200 -> 0
B32: เวลาที่จัดเสร็จ......................................... เวลาที่จัดเสร็จ............................................ | G32: เลขซีล/สี.....................................................

Sheet นครสวรรค์(1)
A1: บริษัท แวลู่พลัส รีเทล จำกัด | G1: รถคันที่ : | H1: 1/1
G2: วันที่ :
A3: ใบจัดสินค้า
A4: ลูกค้า | B4: บริษัท ซีพี ออลล์ จำกัด | D4: สถานที่จัดส่ง | F4: BDC.นครสวรรค์
A5: IV | D5: วันที่ส่ง | J5: คำวนตะกร้า
J6: ตะกร้าเต็ม | L6: ตะกร้าเศษ
A7: ลำดับ | B7: ชื่อสินค้า | C7: บรรจุ | D7: จำนวน | E7: หน่วย | F7: MFD | G7: BBF/EXP | H7: อายุคงเหลือ (วัน) | J7: ใบ | K7: ชิ้น | L7: ใบ | M7: ชิ้น | N7: เกณฑ์ | O7: คงเหลือวันที่ส่งได้
A8: 1 | B8: NEWยูมิยูมิ มิลค์เค้ก 55กรัม | C8: =SUMIF(Data!E:E,B8,Data!F:F) -> 42 | E8: ชิ้น | H8: =+G8-$D$6 -> 0 | J8: =ROUNDDOWN((D8/C8),0) -> 0 | K8: =SUMIF(Data!E:E,'มหาชัย(2)'!B8,Data!F:F)*J8 -> 0 | L8: =ROUNDUP((M8/C8),0) -> 0 | M8: =D8-K8 -> 0 | N8: =INDEX(Data!C:C,MATCH(F4,Data!B:B,0)) -> 60 | O8: =H8-N8 -> -60
A9: 2 | B9: ใหม่ !! ยูมิยูมิ เค้กไข่ชีส 78กรัม | C9: =SUMIF(Data!E:E,B9,Data!F:F) -> 36 | E9: ชิ้น | H9: =+G9-$D$6 -> 0 | J9: =ROUNDDOWN((D9/C9),0) -> 0 | K9: =SUMIF(Data!E:E,'มหาชัย(2)'!B9,Data!F:F)*J9 -> 0 | L9: =ROUNDUP((M9/C9),0) -> 0 | M9: =D9-K9 -> 0 | N9: =INDEX(Data!C:C,MATCH(F5,Data!B:B,0)) -> #N/A | O9: =H9-N9 -> #N/A
A10: 3 | B10: ยูมิยูมิ เค้กอัลมอนด์ 75กรัม | C10: =SUMIF(Data!E:E,B10,Data!F:F) -> 42 | E10: ชิ้น | H10: =+G10-$D$6 -> 0 | J10: =ROUNDDOWN((D10/C10),0) -> 0 | K10: =SUMIF(Data!E:E,'มหาชัย(2)'!B10,Data!F:F)*J10 -> 0 | L10: =ROUNDUP((M10/C10),0) -> 0 | M10: =D10-K10 -> 0 | N10: =INDEX(Data!C:C,MATCH(F6,Data!B:B,0)) -> #N/A | O10: =H10-N10 -> #N/A
A11: 4 | B11: ยูมิยูมิ โรลช็อกโกแลตเค้ก 55กรัม | C11: =SUMIF(Data!E:E,B11,Data!F:F) -> 50 | E11: ชิ้น | H11: =+G11-$D$6 -> 0 | J11: =ROUNDDOWN((D11/C11),0) -> 0 | K11: =SUMIF(Data!E:E,'มหาชัย(2)'!B11,Data!F:F)*J11 -> 0 | L11: =ROUNDUP((M11/C11),0) -> 0 | M11: =D11-K11 -> 0 | N11: =INDEX(Data!C:C,MATCH(F7,Data!B:B,0)) -> #N/A | O11: =H11-N11 -> #N/A
A12: 5 | B12: ยูมิยูมิ มินิครีมเค้ก 40กรัม | C12: =SUMIF(Data!E:E,B12,Data!F:F) -> 81 | E12: ชิ้น | H12: =+G12-$D$6 -> 0 | J12: =ROUNDDOWN((D12/C12),0) -> 0 | K12: =SUMIF(Data!E:E,'มหาชัย(2)'!B12,Data!F:F)*J12 -> 0 | L12: =ROUNDUP((M12/C12),0) -> 0 | M12: =D12-K12 -> 0 | N12: =INDEX(Data!C:C,MATCH(F8,Data!B:B,0)) -> #N/A | O12: =H12-N12 -> #N/A
A13: 6 | B13: ยูมิยูมิ เค้กครีมสลัดไก่หยอง 75กรัม | C13: =SUMIF(Data!E:E,B13,Data!F:F) -> 42 | E13: ชิ้น | H13: =+G13-$D$6 -> 0 | J13: =ROUNDDOWN((D13/C13),0) -> 0 | K13: =SUMIF(Data!E:E,'มหาชัย(2)'!B13,Data!F:F)*J13 -> 0 | L13: =ROUNDUP((M13/C13),0) -> 0 | M13: =D13-K13 -> 0 | N13: =INDEX(Data!C:C,MATCH(F9,Data!B:B,0)) -> #N/A | O13: =H13-N13 -> #N/A
A14: 7 | B14: ยูมิยูมิ ชิสึเค้ก 70กรัม | C14: =SUMIF(Data!E:E,B14,Data!F:F) -> 32 | E14: ชิ้น | H14: =+G14-$D$6 -> 0 | J14: =ROUNDDOWN((D14/C14),0) -> 0 | K14: =SUMIF(Data!E:E,'มหาชัย(2)'!B14,Data!F:F)*J14 -> 0 | L14: =ROUNDUP((M14/C14),0) -> 0 | M14: =D14-K14 -> 0 | N14: =INDEX(Data!C:C,MATCH(F10,Data!B:B,0)) -> #N/A | O14: =H14-N14 -> #N/A
A15: 8 | B15: ยูมิยูมิ บลูเบอร์รี่เค้ก 52กรัม | C15: =SUMIF(Data!E:E,B15,Data!F:F) -> 70 | E15: ชิ้น | H15: =+G15-$D$6 -> 0 | J15: =ROUNDDOWN((D15/C15),0) -> 0 | K15: =SUMIF(Data!E:E,'มหาชัย(2)'!B15,Data!F:F)*J15 -> 0 | L15: =ROUNDUP((M15/C15),0) -> 0 | M15: =D15-K15 -> 0 | N15: =INDEX(Data!C:C,MATCH(F11,Data!B:B,0)) -> #N/A | O15: =H15-N15 -> #N/A
A16: 9 | B16: ยูมิยูมิ เค้กสาหร่ายไก่หยอง 75กรัม | C16: =SUMIF(Data!E:E,B16,Data!F:F) -> 45 | E16: ชิ้น | H16: =+G16-$D$6 -> 0 | J16: =ROUNDDOWN((D16/C16),0) -> 0 | K16: =SUMIF(Data!E:E,'มหาชัย(2)'!B16,Data!F:F)*J16 -> 0 | L16: =ROUNDUP((M16/C16),0) -> 0 | M16: =D16-K16 -> 0 | N16: =INDEX(Data!C:C,MATCH(F12,Data!B:B,0)) -> #N/A | O16: =H16-N16 -> #N/A
A17: 10 | B17: ยูมิยูมิ เค้กช็อกโกแลตเฮเซลนัท 75กรัม | C17: =SUMIF(Data!E:E,B17,Data!F:F) -> 48 | E17: ชิ้น | H17: =+G17-$D$6 -> 0 | J17: =ROUNDDOWN((D17/C17),0) -> 0 | K17: =SUMIF(Data!E:E,'มหาชัย(2)'!B17,Data!F:F)*J17 -> 0 | L17: =ROUNDUP((M17/C17),0) -> 0 | M17: =D17-K17 -> 0 | N17: =INDEX(Data!C:C,MATCH(F13,Data!B:B,0)) -> #N/A | O17: =H17-N17 -> #N/A
A18: 11 | B18: ยูมิยูมิ ชิฟฟอนชีสเค้ก 75กรัม | C18: =SUMIF(Data!E:E,B18,Data!F:F) -> 48 | E18: ชิ้น | H18: =+G18-$D$6 -> 0 | J18: =ROUNDDOWN((D18/C18),0) -> 0 | K18: =SUMIF(Data!E:E,'มหาชัย(2)'!B18,Data!F:F)*J18 -> 0 | L18: =ROUNDUP((M18/C18),0) -> 0 | M18: =D18-K18 -> 0 | N18: =INDEX(Data!C:C,MATCH(F14,Data!B:B,0)) -> #N/A | O18: =H18-N18 -> #N/A
A19: 12 | B19: วาฟเฟิลครีมโคโคนัทมิลค์ 62กรัม | C19: =SUMIF(Data!E:E,B19,Data!F:F) -> 60 | E19: ชิ้น | H19: =+G19-$D$6 -> 0 | J19: =ROUNDDOWN((D19/C19),0) -> 0 | K19: =SUMIF(Data!E:E,'มหาชัย(2)'!B19,Data!F:F)*J19 -> 0 | L19: =ROUNDUP((M19/C19),0) -> 0 | M19: =D19-K19 -> 0 | N19: =INDEX(Data!C:C,MATCH(F15,Data!B:B,0)) -> #N/A | O19: =H19-N19 -> #N/A
... A26: 19 | B26: ยูมิยูมิ มินิเค้กไส้ครีมกล้วยหอม 40กรัม | C26: =SUMIF(Data!E:E,B26,Data!F:F) -> 81 | E26: ชิ้น | H26: =+G26-$D$6 -> 0 | J26: =ROUNDDOWN((D26/C26),0) -> 0 | K26: =SUMIF(Data!E:E,'มหาชัย(2)'!B26,Data!F:F)*J26 -> 0 | L26: =ROUNDUP((M26/C26),0) -> 0 | M26: =D26-K26 -> 0 | N26: =INDEX(Data!C:C,MATCH(F22,Data!B:B,0)) -> #N/A | O26: =H26-N26 -> #N/A
A27: ยอดรวมสินค้า | J27: ตะกร้าเต็ม | K27: ตะกร้าเศษ | L27: รวมตะกร้า
J28: =SUM($J$8:$J$26) -> 0 | K28: =SUM($L$8:$L$26) -> 0 | L28: =SUM(J28:K28) -> 0
B30: ผู้รับผิดชอบ.......................................... ผู้ตรวจ (เช็คเกอร์)....................................... | G30: พนักงานขนส่ง..........................................
B31: วันที่จัดเสร็จ.......................................... วันที่จัดเสร็จ................................................ | G31: ทะเบียนขนส่ง.............................................
B32: เวลาที่จัดเสร็จ......................................... เวลาที่จัดเสร็จ............................................ | G32: เลขซีล/สี.....................................................

Sheet นครราชสีมา(1)
A1: บริษัท แวลู่พลัส รีเทล จำกัด | G1: รถคันที่ : | H1: 1/1
G2: วันที่ :
A3: ใบจัดสินค้า
A4: ลูกค้า | B4: บริษัท ซีพี ออลล์ จำกัด | D4: สถานที่จัดส่ง | F4: BDC.นครราชสีมา
A5: IV | D5: วันที่ส่ง | J5: คำวนตะกร้า
J6: ตะกร้าเต็ม | L6: ตะกร้าเศษ
A7: ลำดับ | B7: ชื่อสินค้า | C7: บรรจุ | D7: จำนวน | E7: หน่วย | F7: MFD | G7: BBF/EXP | H7: อายุคงเหลือ (วัน) | J7: ใบ | K7: ชิ้น | L7: ใบ | M7: ชิ้น | N7: เกณฑ์ | O7: คงเหลือวันที่ส่งได้
A8: 1 | B8: NEWยูมิยูมิ มิลค์เค้ก 55กรัม | C8: =SUMIF(Data!E:E,B8,Data!F:F) -> 42 | E8: ชิ้น | H8: =+G8-$D$6 -> 0 | J8: =ROUNDDOWN((D8/C8),0) -> 0 | K8: =SUMIF(Data!E:E,'มหาชัย(2)'!B8,Data!F:F)*J8 -> 0 | L8: =ROUNDUP((M8/C8),0) -> 0 | M8: =D8-K8 -> 0 | N8: =INDEX(Data!C:C,MATCH(F4,Data!B:B,0)) -> 60 | O8: =H8-N8 -> -60
A9: 2 | B9: ใหม่ !! ยูมิยูมิ เค้กไข่ชีส 78กรัม | C9: =SUMIF(Data!E:E,B9,Data!F:F) -> 36 | E9: ชิ้น | H9: =+G9-$D$6 -> 0 | J9: =ROUNDDOWN((D9/C9),0) -> 0 | K9: =SUMIF(Data!E:E,'มหาชัย(2)'!B9,Data!F:F)*J9 -> 0 | L9: =ROUNDUP((M9/C9),0) -> 0 | M9: =D9-K9 -> 0 | N9: =INDEX(Data!C:C,MATCH(F5,Data!B:B,0)) -> #N/A | O9: =H9-N9 -> #N/A
A10: 3 | B10: ยูมิยูมิ เค้กอัลมอนด์ 75กรัม | C10: =SUMIF(Data!E:E,B10,Data!F:F) -> 42 | E10: ชิ้น | H10: =+G10-$D$6 -> 0 | J10: =ROUNDDOWN((D10/C10),0) -> 0 | K10: =SUMIF(Data!E:E,'มหาชัย(2)'!B10,Data!F:F)*J10 -> 0 | L10: =ROUNDUP((M10/C10),0) -> 0 | M10: =D10-K10 -> 0 | N10: =INDEX(Data!C:C,MATCH(F6,Data!B:B,0)) -> #N/A | O10: =H10-N10 -> #N/A
A11: 4 | B11: ยูมิยูมิ โรลช็อกโกแลตเค้ก 55กรัม | C11: =SUMIF(Data!E:E,B11,Data!F:F) -> 50 | E11: ชิ้น | H11: =+G11-$D$6 -> 0 | J11: =ROUNDDOWN((D11/C11),0) -> 0 | K11: =SUMIF(Data!E:E,'มหาชัย(2)'!B11,Data!F:F)*J11 -> 0 | L11: =ROUNDUP((M11/C11),0) -> 0 | M11: =D11-K11 -> 0 | N11: =INDEX(Data!C:C,MATCH(F7,Data!B:B,0)) -> #N/A | O11: =H11-N11 -> #N/A
A12: 5 | B12: ยูมิยูมิ มินิครีมเค้ก 40กรัม | C12: =SUMIF(Data!E:E,B12,Data!F:F) -> 81 | E12: ชิ้น | H12: =+G12-$D$6 -> 0 | J12: =ROUNDDOWN((D12/C12),0) -> 0 | K12: =SUMIF(Data!E:E,'มหาชัย(2)'!B12,Data!F:F)*J12 -> 0 | L12: =ROUNDUP((M12/C12),0) -> 0 | M12: =D12-K12 -> 0 | N12: =INDEX(Data!C:C,MATCH(F8,Data!B:B,0)) -> #N/A | O12: =H12-N12 -> #N/A
A13: 6 | B13: ยูมิยูมิ เค้กครีมสลัดไก่หยอง 75กรัม | C13: =SUMIF(Data!E:E,B13,Data!F:F) -> 42 | E13: ชิ้น | H13: =+G13-$D$6 -> 0 | J13: =ROUNDDOWN((D13/C13),0) -> 0 | K13: =SUMIF(Data!E:E,'มหาชัย(2)'!B13,Data!F:F)*J13 -> 0 | L13: =ROUNDUP((M13/C13),0) -> 0 | M13: =D13-K13 -> 0 | N13: =INDEX(Data!C:C,MATCH(F9,Data!B:B,0)) -> #N/A | O13: =H13-N13 -> #N/A
A14: 7 | B14: ยูมิยูมิ ชิสึเค้ก 70กรัม | C14: =SUMIF(Data!E:E,B14,Data!F:F) -> 32 | E14: ชิ้น | H14: =+G14-$D$6 -> 0 | J14: =ROUNDDOWN((D14/C14),0) -> 0 | K14: =SUMIF(Data!E:E,'มหาชัย(2)'!B14,Data!F:F)*J14 -> 0 | L14: =ROUNDUP((M14/C14),0) -> 0 | M14: =D14-K14 -> 0 | N14: =INDEX(Data!C:C,MATCH(F10,Data!B:B,0)) -> #N/A | O14: =H14-N14 -> #N/A
A15: 8 | B15: ยูมิยูมิ บลูเบอร์รี่เค้ก 52กรัม | C15: =SUMIF(Data!E:E,B15,Data!F:F) -> 70 | E15: ชิ้น | H15: =+G15-$D$6 -> 0 | J15: =ROUNDDOWN((D15/C15),0) -> 0 | K15: =SUMIF(Data!E:E,'มหาชัย(2)'!B15,Data!F:F)*J15 -> 0 | L15: =ROUNDUP((M15/C15),0) -> 0 | M15: =D15-K15 -> 0 | N15: =INDEX(Data!C:C,MATCH(F11,Data!B:B,0)) -> #N/A | O15: =H15-N15 -> #N/A
A16: 9 | B16: ยูมิยูมิ เค้กสาหร่ายไก่หยอง 75กรัม | C16: =SUMIF(Data!E:E,B16,Data!F:F) -> 45 | E16: ชิ้น | H16: =+G16-$D$6 -> 0 | J16: =ROUNDDOWN((D16/C16),0) -> 0 | K16: =SUMIF(Data!E:E,'มหาชัย(2)'!B16,Data!F:F)*J16 -> 0 | L16: =ROUNDUP((M16/C16),0) -> 0 | M16: =D16-K16 -> 0 | N16: =INDEX(Data!C:C,MATCH(F12,Data!B:B,0)) -> #N/A | O16: =H16-N16 -> #N/A
A17: 10 | B17: ยูมิยูมิ เค้กช็อกโกแลตเฮเซลนัท 75กรัม | C17: =SUMIF(Data!E:E,B17,Data!F:F) -> 48 | E17: ชิ้น | H17: =+G17-$D$6 -> 0 | J17: =ROUNDDOWN((D17/C17),0) -> 0 | K17: =SUMIF(Data!E:E,'มหาชัย(2)'!B17,Data!F:F)*J17 -> 0 | L17: =ROUNDUP((M17/C17),0) -> 0 | M17: =D17-K17 -> 0 | N17: =INDEX(Data!C:C,MATCH(F13,Data!B:B,0)) -> #N/A | O17: =H17-N17 -> #N/A
A18: 11 | B18: ยูมิยูมิ ชิฟฟอนชีสเค้ก 75กรัม | C18: =SUMIF(Data!E:E,B18,Data!F:F) -> 48 | E18: ชิ้น | H18: =+G18-$D$6 -> 0 | J18: =ROUNDDOWN((D18/C18),0) -> 0 | K18: =SUMIF(Data!E:E,'มหาชัย(2)'!B18,Data!F:F)*J18 -> 0 | L18: =ROUNDUP((M18/C18),0) -> 0 | M18: =D18-K18 -> 0 | N18: =INDEX(Data!C:C,MATCH(F14,Data!B:B,0)) -> #N/A | O18: =H18-N18 -> #N/A
A19: 12 | B19: วาฟเฟิลครีมโคโคนัทมิลค์ 62กรัม | C19: =SUMIF(Data!E:E,B19,Data!F:F) -> 60 | E19: ชิ้น | H19: =+G19-$D$6 -> 0 | J19: =ROUNDDOWN((D19/C19),0) -> 0 | K19: =SUMIF(Data!E:E,'มหาชัย(2)'!B19,Data!F:F)*J19 -> 0 | L19: =ROUNDUP((M19/C19),0) -> 0 | M19: =D19-K19 -> 0 | N19: =INDEX(Data!C:C,MATCH(F15,Data!B:B,0)) -> #N/A | O19: =H19-N19 -> #N/A
... A26: 19 | B26: ยูมิยูมิ มินิเค้กไส้ครีมกล้วยหอม 40กรัม | C26: =SUMIF(Data!E:E,B26,Data!F:F) -> 81 | E26: ชิ้น | H26: =+G26-$D$6 -> 0 | J26: =ROUNDDOWN((D26/C26),0) -> 0 | K26: =SUMIF(Data!E:E,'มหาชัย(2)'!B26,Data!F:F)*J26 -> 0 | L26: =ROUNDUP((M26/C26),0) -> 0 | M26: =D26-K26 -> 0 | N26: =INDEX(Data!C:C,MATCH(F22,Data!B:B,0)) -> #N/A | O26: =H26-N26 -> #N/A
A27: ยอดรวมสินค้า | J27: ตะกร้าเต็ม | K27: ตะกร้าเศษ | L27: รวมตะกร้า
J28: =SUM($J$8:$J$26) -> 0 | K28: =SUM($L$8:$L$26) -> 0 | L28: =SUM(J28:K28) -> 0
B30: ผู้รับผิดชอบ.......................................... ผู้ตรวจ (เช็คเกอร์)....................................... | G30: พนักงานขนส่ง..........................................
B31: วันที่จัดเสร็จ.......................................... วันที่จัดเสร็จ................................................ | G31: ทะเบียนขนส่ง.............................................
B32: เวลาที่จัดเสร็จ......................................... เวลาที่จัดเสร็จ............................................ | G32: เลขซีล/สี.....................................................

Sheet เชียงใหม่(1)
A1: บริษัท แวลู่พลัส รีเทล จำกัด | G1: รถคันที่ : | H1: 1/1
G2: วันที่ :
A3: ใบจัดสินค้า
A4: ลูกค้า | B4: บริษัท ซีพี ออลล์ จำกัด | D4: สถานที่จัดส่ง | F4: BDC.เชียงใหม่
A5: IV | D5: วันที่ส่ง | J5: คำวนตะกร้า
J6: ตะกร้าเต็ม | L6: ตะกร้าเศษ
A7: ลำดับ | B7: ชื่อสินค้า | C7: บรรจุ | D7: จำนวน | E7: หน่วย | F7: MFD | G7: BBF/EXP | H7: อายุคงเหลือ (วัน) | J7: ใบ | K7: ชิ้น | L7: ใบ | M7: ชิ้น | N7: เกณฑ์ | O7: คงเหลือวันที่ส่งได้
A8: 1 | B8: NEWยูมิยูมิ มิลค์เค้ก 55กรัม | C8: =SUMIF(Data!E:E,B8,Data!F:F) -> 42 | E8: ชิ้น | H8: =+G8-$D$6 -> 0 | J8: =ROUNDDOWN((D8/C8),0) -> 0 | K8: =SUMIF(Data!E:E,'มหาชัย(2)'!B8,Data!F:F)*J8 -> 0 | L8: =ROUNDUP((M8/C8),0) -> 0 | M8: =D8-K8 -> 0 | N8: =INDEX(Data!C:C,MATCH(F4,Data!B:B,0)) -> 60 | O8: =H8-N8 -> -60
A9: 2 | B9: ใหม่ !! ยูมิยูมิ เค้กไข่ชีส 78กรัม | C9: =SUMIF(Data!E:E,B9,Data!F:F) -> 36 | E9: ชิ้น | H9: =+G9-$D$6 -> 0 | J9: =ROUNDDOWN((D9/C9),0) -> 0 | K9: =SUMIF(Data!E:E,'มหาชัย(2)'!B9,Data!F:F)*J9 -> 0 | L9: =ROUNDUP((M9/C9),0) -> 0 | M9: =D9-K9 -> 0 | N9: =INDEX(Data!C:C,MATCH(F5,Data!B:B,0)) -> #N/A | O9: =H9-N9 -> #N/A
A10: 3 | B10: ยูมิยูมิ เค้กอัลมอนด์ 75กรัม | C10: =SUMIF(Data!E:E,B10,Data!F:F) -> 42 | E10: ชิ้น | H10: =+G10-$D$6 -> 0 | J10: =ROUNDDOWN((D10/C10),0) -> 0 | K10: =SUMIF(Data!E:E,'มหาชัย(2)'!B10,Data!F:F)*J10 -> 0 | L10: =ROUNDUP((M10/C10),0) -> 0 | M10: =D10-K10 -> 0 | N10: =INDEX(Data!C:C,MATCH(F6,Data!B:B,0)) -> #N/A | O10: =H10-N10 -> #N/A
A11: 4 | B11: ยูมิยูมิ โรลช็อกโกแลตเค้ก 55กรัม | C11: =SUMIF(Data!E:E,B11,Data!F:F) -> 50 | E11: ชิ้น | H11: =+G11-$D$6 -> 0 | J11: =ROUNDDOWN((D11/C11),0) -> 0 | K11: =SUMIF(Data!E:E,'มหาชัย(2)'!B11,Data!F:F)*J11 -> 0 | L11: =ROUNDUP((M11/C11),0) -> 0 | M11: =D11-K11 -> 0 | N11: =INDEX(Data!C:C,MATCH(F7,Data!B:B,0)) -> #N/A | O11: =H11-N11 -> #N/A
A12: 5 | B12: ยูมิยูมิ มินิครีมเค้ก 40กรัม | C12: =SUMIF(Data!E:E,B12,Data!F:F) -> 81 | E12: ชิ้น | H12: =+G12-$D$6 -> 0 | J12: =ROUNDDOWN((D12/C12),0) -> 0 | K12: =SUMIF(Data!E:E,'มหาชัย(2)'!B12,Data!F:F)*J12 -> 0 | L12: =ROUNDUP((M12/C12),0) -> 0 | M12: =D12-K12 -> 0 | N12: =INDEX(Data!C:C,MATCH(F8,Data!B:B,0)) -> #N/A | O12: =H12-N12 -> #N/A
A13: 6 | B13: ยูมิยูมิ เค้กครีมสลัดไก่หยอง 75กรัม | C13: =SUMIF(Data!E:E,B13,Data!F:F) -> 42 | E13: ชิ้น | H13: =+G13-$D$6 -> 0 | J13: =ROUNDDOWN((D13/C13),0) -> 0 | K13: =SUMIF(Data!E:E,'มหาชัย(2)'!B13,Data!F:F)*J13 -> 0 | L13: =ROUNDUP((M13/C13),0) -> 0 | M13: =D13-K13 -> 0 | N13: =INDEX(Data!C:C,MATCH(F9,Data!B:B,0)) -> #N/A | O13: =H13-N13 -> #N/A
A14: 7 | B14: ยูมิยูมิ ชิสึเค้ก 70กรัม | C14: =SUMIF(Data!E:E,B14,Data!F:F) -> 32 | E14: ชิ้น | H14: =+G14-$D$6 -> 0 | J14: =ROUNDDOWN((D14/C14),0) -> 0 | K14: =SUMIF(Data!E:E,'มหาชัย(2)'!B14,Data!F:F)*J14 -> 0 | L14: =ROUNDUP((M14/C14),0) -> 0 | M14: =D14-K14 -> 0 | N14: =INDEX(Data!C:C,MATCH(F10,Data!B:B,0)) -> #N/A | O14: =H14-N14 -> #N/A
A15: 8 | B15: ยูมิยูมิ บลูเบอร์รี่เค้ก 52กรัม | C15: =SUMIF(Data!E:E,B15,Data!F:F) -> 70 | E15: ชิ้น | H15: =+G15-$D$6 -> 0 | J15: =ROUNDDOWN((D15/C15),0) -> 0 | K15: =SUMIF(Data!E:E,'มหาชัย(2)'!B15,Data!F:F)*J15 -> 0 | L15: =ROUNDUP((M15/C15),0) -> 0 | M15: =D15-K15 -> 0 | N15: =INDEX(Data!C:C,MATCH(F11,Data!B:B,0)) -> #N/A | O15: =H15-N15 -> #N/A
A16: 9 | B16: ยูมิยูมิ เค้กสาหร่ายไก่หยอง 75กรัม | C16: =SUMIF(Data!E:E,B16,Data!F:F) -> 45 | E16: ชิ้น | H16: =+G16-$D$6 -> 0 | J16: =ROUNDDOWN((D16/C16),0) -> 0 | K16: =SUMIF(Data!E:E,'มหาชัย(2)'!B16,Data!F:F)*J16 -> 0 | L16: =ROUNDUP((M16/C16),0) -> 0 | M16: =D16-K16 -> 0 | N16: =INDEX(Data!C:C,MATCH(F12,Data!B:B,0)) -> #N/A | O16: =H16-N16 -> #N/A
A17: 10 | B17: ยูมิยูมิ เค้กช็อกโกแลตเฮเซลนัท 75กรัม | C17: =SUMIF(Data!E:E,B17,Data!F:F) -> 48 | E17: ชิ้น | H17: =+G17-$D$6 -> 0 | J17: =ROUNDDOWN((D17/C17),0) -> 0 | K17: =SUMIF(Data!E:E,'มหาชัย(2)'!B17,Data!F:F)*J17 -> 0 | L17: =ROUNDUP((M17/C17),0) -> 0 | M17: =D17-K17 -> 0 | N17: =INDEX(Data!C:C,MATCH(F13,Data!B:B,0)) -> #N/A | O17: =H17-N17 -> #N/A
A18: 11 | B18: ยูมิยูมิ ชิฟฟอนชีสเค้ก 75กรัม | C18: =SUMIF(Data!E:E,B18,Data!F:F) -> 48 | E18: ชิ้น | H18: =+G18-$D$6 -> 0 | J18: =ROUNDDOWN((D18/C18),0) -> 0 | K18: =SUMIF(Data!E:E,'มหาชัย(2)'!B18,Data!F:F)*J18 -> 0 | L18: =ROUNDUP((M18/C18),0) -> 0 | M18: =D18-K18 -> 0 | N18: =INDEX(Data!C:C,MATCH(F14,Data!B:B,0)) -> #N/A | O18: =H18-N18 -> #N/A
A19: 12 | B19: วาฟเฟิลครีมโคโคนัทมิลค์ 62กรัม | C19: =SUMIF(Data!E:E,B19,Data!F:F) -> 60 | E19: ชิ้น | H19: =+G19-$D$6 -> 0 | J19: =ROUNDDOWN((D19/C19),0) -> 0 | K19: =SUMIF(Data!E:E,'มหาชัย(2)'!B19,Data!F:F)*J19 -> 0 | L19: =ROUNDUP((M19/C19),0) -> 0 | M19: =D19-K19 -> 0 | N19: =INDEX(Data!C:C,MATCH(F15,Data!B:B,0)) -> #N/A | O19: =H19-N19 -> #N/A
... A26: 19 | B26: ยูมิยูมิ มินิเค้กไส้ครีมกล้วยหอม 40กรัม | C26: =SUMIF(Data!E:E,B26,Data!F:F) -> 81 | E26: ชิ้น | H26: =+G26-$D$6 -> 0 | J26: =ROUNDDOWN((D26/C26),0) -> 0 | K26: =SUMIF(Data!E:E,'มหาชัย(2)'!B26,Data!F:F)*J26 -> 0 | L26: =ROUNDUP((M26/C26),0) -> 0 | M26: =D26-K26 -> 0 | N26: =INDEX(Data!C:C,MATCH(F22,Data!B:B,0)) -> #N/A | O26: =H26-N26 -> #N/A
A27: ยอดรวมสินค้า | J27: ตะกร้าเต็ม | K27: ตะกร้าเศษ | L27: รวมตะกร้า
J28: =SUM($J$8:$J$26) -> 0 | K28: =SUM($L$8:$L$26) -> 0 | L28: =SUM(J28:K28) -> 0
B30: ผู้รับผิดชอบ.......................................... ผู้ตรวจ (เช็คเกอร์)....................................... | G30: พนักงานขนส่ง..........................................
B31: วันที่จัดเสร็จ.......................................... วันที่จัดเสร็จ................................................ | G31: ทะเบียนขนส่ง.............................................
B32: เวลาที่จัดเสร็จ......................................... เวลาที่จัดเสร็จ............................................ | G32: เลขซีล/สี.....................................................

Sheet เชียงใหม่(2)
A1: บริษัท แวลู่พลัส รีเทล จำกัด | G1: รถคันที่ : | H1: 1/1
G2: วันที่ :
A3: ใบจัดสินค้า
A4: ลูกค้า | B4: บริษัท ซีพี ออลล์ จำกัด | D4: สถานที่จัดส่ง | F4: BDC.เชียงใหม่
A5: IV | D5: วันที่ส่ง | J5: คำวนตะกร้า
J6: ตะกร้าเต็ม | L6: ตะกร้าเศษ
A7: ลำดับ | B7: ชื่อสินค้า | C7: บรรจุ | D7: จำนวน | E7: หน่วย | F7: MFD | G7: BBF/EXP | H7: อายุคงเหลือ (วัน) | J7: ใบ | K7: ชิ้น | L7: ใบ | M7: ชิ้น | N7: เกณฑ์ | O7: คงเหลือวันที่ส่งได้
A8: 1 | B8: NEWยูมิยูมิ มิลค์เค้ก 55กรัม | C8: =SUMIF(Data!E:E,B8,Data!F:F) -> 42 | E8: ชิ้น | H8: =+G8-$D$6 -> 0 | J8: =ROUNDDOWN((D8/C8),0) -> 0 | K8: =SUMIF(Data!E:E,'มหาชัย(2)'!B8,Data!F:F)*J8 -> 0 | L8: =ROUNDUP((M8/C8),0) -> 0 | M8: =D8-K8 -> 0 | N8: =INDEX(Data!C:C,MATCH(F4,Data!B:B,0)) -> 60 | O8: =H8-N8 -> -60
A9: 2 | B9: ใหม่ !! ยูมิยูมิ เค้กไข่ชีส 78กรัม | C9: =SUMIF(Data!E:E,B9,Data!F:F) -> 36 | E9: ชิ้น | H9: =+G9-$D$6 -> 0 | J9: =ROUNDDOWN((D9/C9),0) -> 0 | K9: =SUMIF(Data!E:E,'มหาชัย(2)'!B9,Data!F:F)*J9 -> 0 | L9: =ROUNDUP((M9/C9),0) -> 0 | M9: =D9-K9 -> 0 | N9: =INDEX(Data!C:C,MATCH(F5,Data!B:B,0)) -> #N/A | O9: =H9-N9 -> #N/A
A10: 3 | B10: ยูมิยูมิ เค้กอัลมอนด์ 75กรัม | C10: =SUMIF(Data!E:E,B10,Data!F:F) -> 42 | E10: ชิ้น | H10: =+G10-$D$6 -> 0 | J10: =ROUNDDOWN((D10/C10),0) -> 0 | K10: =SUMIF(Data!E:E,'มหาชัย(2)'!B10,Data!F:F)*J10 -> 0 | L10: =ROUNDUP((M10/C10),0) -> 0 | M10: =D10-K10 -> 0 | N10: =INDEX(Data!C:C,MATCH(F6,Data!B:B,0)) -> #N/A | O10: =H10-N10 -> #N/A
A11: 4 | B11: ยูมิยูมิ โรลช็อกโกแลตเค้ก 55กรัม | C11: =SUMIF(Data!E:E,B11,Data!F:F) -> 50 | E11: ชิ้น | H11: =+G11-$D$6 -> 0 | J11: =ROUNDDOWN((D11/C11),0) -> 0 | K11: =SUMIF(Data!E:E,'มหาชัย(2)'!B11,Data!F:F)*J11 -> 0 | L11: =ROUNDUP((M11/C11),0) -> 0 | M11: =D11-K11 -> 0 | N11: =INDEX(Data!C:C,MATCH(F7,Data!B:B,0)) -> #N/A | O11: =H11-N11 -> #N/A
A12: 5 | B12: ยูมิยูมิ มินิครีมเค้ก 40กรัม | C12: =SUMIF(Data!E:E,B12,Data!F:F) -> 81 | E12: ชิ้น | H12: =+G12-$D$6 -> 0 | J12: =ROUNDDOWN((D12/C12),0) -> 0 | K12: =SUMIF(Data!E:E,'มหาชัย(2)'!B12,Data!F:F)*J12 -> 0 | L12: =ROUNDUP((M12/C12),0) -> 0 | M12: =D12-K12 -> 0 | N12: =INDEX(Data!C:C,MATCH(F8,Data!B:B,0)) -> #N/A | O12: =H12-N12 -> #N/A
A13: 6 | B13: ยูมิยูมิ เค้กครีมสลัดไก่หยอง 75กรัม | C13: =SUMIF(Data!E:E,B13,Data!F:F) -> 42 | E13: ชิ้น | H13: =+G13-$D$6 -> 0 | J13: =ROUNDDOWN((D13/C13),0) -> 0 | K13: =SUMIF(Data!E:E,'มหาชัย(2)'!B13,Data!F:F)*J13 -> 0 | L13: =ROUNDUP((M13/C13),0) -> 0 | M13: =D13-K13 -> 0 | N13: =INDEX(Data!C:C,MATCH(F9,Data!B:B,0)) -> #N/A | O13: =H13-N13 -> #N/A
A14: 7 | B14: ยูมิยูมิ ชิสึเค้ก 70กรัม | C14: =SUMIF(Data!E:E,B14,Data!F:F) -> 32 | E14: ชิ้น | H14: =+G14-$D$6 -> 0 | J14: =ROUNDDOWN((D14/C14),0) -> 0 | K14: =SUMIF(Data!E:E,'มหาชัย(2)'!B14,Data!F:F)*J14 -> 0 | L14: =ROUNDUP((M14/C14),0) -> 0 | M14: =D14-K14 -> 0 | N14: =INDEX(Data!C:C,MATCH(F10,Data!B:B,0)) -> #N/A | O14: =H14-N14 -> #N/A
A15: 8 | B15: ยูมิยูมิ บลูเบอร์รี่เค้ก 52กรัม | C15: =SUMIF(Data!E:E,B15,Data!F:F) -> 70 | E15: ชิ้น | H15: =+G15-$D$6 -> 0 | J15: =ROUNDDOWN((D15/C15),0) -> 0 | K15: =SUMIF(Data!E:E,'มหาชัย(2)'!B15,Data!F:F)*J15 -> 0 | L15: =ROUNDUP((M15/C15),0) -> 0 | M15: =D15-K15 -> 0 | N15: =INDEX(Data!C:C,MATCH(F11,Data!B:B,0)) -> #N/A | O15: =H15-N15 -> #N/A
A16: 9 | B16: ยูมิยูมิ เค้กสาหร่ายไก่หยอง 75กรัม | C16: =SUMIF(Data!E:E,B16,Data!F:F) -> 45 | E16: ชิ้น | H16: =+G16-$D$6 -> 0 | J16: =ROUNDDOWN((D16/C16),0) -> 0 | K16: =SUMIF(Data!E:E,'มหาชัย(2)'!B16,Data!F:F)*J16 -> 0 | L16: =ROUNDUP((M16/C16),0) -> 0 | M16: =D16-K16 -> 0 | N16: =INDEX(Data!C:C,MATCH(F12,Data!B:B,0)) -> #N/A | O16: =H16-N16 -> #N/A
A17: 10 | B17: ยูมิยูมิ เค้กช็อกโกแลตเฮเซลนัท 75กรัม | C17: =SUMIF(Data!E:E,B17,Data!F:F) -> 48 | E17: ชิ้น | H17: =+G17-$D$6 -> 0 | J17: =ROUNDDOWN((D17/C17),0) -> 0 | K17: =SUMIF(Data!E:E,'มหาชัย(2)'!B17,Data!F:F)*J17 -> 0 | L17: =ROUNDUP((M17/C17),0) -> 0 | M17: =D17-K17 -> 0 | N17: =INDEX(Data!C:C,MATCH(F13,Data!B:B,0)) -> #N/A | O17: =H17-N17 -> #N/A
A18: 11 | B18: ยูมิยูมิ ชิฟฟอนชีสเค้ก 75กรัม | C18: =SUMIF(Data!E:E,B18,Data!F:F) -> 48 | E18: ชิ้น | H18: =+G18-$D$6 -> 0 | J18: =ROUNDDOWN((D18/C18),0) -> 0 | K18: =SUMIF(Data!E:E,'มหาชัย(2)'!B18,Data!F:F)*J18 -> 0 | L18: =ROUNDUP((M18/C18),0) -> 0 | M18: =D18-K18 -> 0 | N18: =INDEX(Data!C:C,MATCH(F14,Data!B:B,0)) -> #N/A | O18: =H18-N18 -> #N/A
A19: 12 | B19: วาฟเฟิลครีมโคโคนัทมิลค์ 62กรัม | C19: =SUMIF(Data!E:E,B19,Data!F:F) -> 60 | E19: ชิ้น | H19: =+G19-$D$6 -> 0 | J19: =ROUNDDOWN((D19/C19),0) -> 0 | K19: =SUMIF(Data!E:E,'มหาชัย(2)'!B19,Data!F:F)*J19 -> 0 | L19: =ROUNDUP((M19/C19),0) -> 0 | M19: =D19-K19 -> 0 | N19: =INDEX(Data!C:C,MATCH(F15,Data!B:B,0)) -> #N/A | O19: =H19-N19 -> #N/A
... A26: 19 | B26: ยูมิยูมิ มินิเค้กไส้ครีมกล้วยหอม 40กรัม | C26: =SUMIF(Data!E:E,B26,Data!F:F) -> 81 | E26: ชิ้น | H26: =+G26-$D$6 -> 0 | J26: =ROUNDDOWN((D26/C26),0) -> 0 | K26: =SUMIF(Data!E:E,'มหาชัย(2)'!B26,Data!F:F)*J26 -> 0 | L26: =ROUNDUP((M26/C26),0) -> 0 | M26: =D26-K26 -> 0 | N26: =INDEX(Data!C:C,MATCH(F22,Data!B:B,0)) -> #N/A | O26: =H26-N26 -> #N/A
A27: ยอดรวมสินค้า | D27: =SUM(D8:D23) -> 0 | J27: ตะกร้าเต็ม | K27: ตะกร้าเศษ | L27: รวมตะกร้า
J28: =SUM($J$8:$J$26) -> 0 | K28: =SUM($L$8:$L$26) -> 0 | L28: =SUM(J28:K28) -> 0
B30: ผู้รับผิดชอบ.......................................... ผู้ตรวจ (เช็คเกอร์)....................................... | G30: พนักงานขนส่ง..........................................
B31: วันที่จัดเสร็จ.......................................... วันที่จัดเสร็จ................................................ | G31: ทะเบียนขนส่ง.............................................
B32: เวลาที่จัดเสร็จ......................................... เวลาที่จัดเสร็จ............................................ | G32: เลขซีล/สี.....................................................

Sheet ขอนแก่น(4)
A1: บริษัท แวลู่พลัส รีเทล จำกัด | G1: รถคันที่ : | H1: 1/1
G2: วันที่ :
A3: ใบจัดสินค้า
A4: ลูกค้า | B4: บริษัท ซีพี ออลล์ จำกัด | D4: สถานที่จัดส่ง | F4: BDC.ขอนแก่น
A5: IV | D5: วันที่ส่ง | J5: คำวนตะกร้า
J6: ตะกร้าเต็ม | L6: ตะกร้าเศษ
A7: ลำดับ | B7: ชื่อสินค้า | C7: บรรจุ | D7: จำนวน | E7: หน่วย | F7: MFD | G7: BBF/EXP | H7: อายุคงเหลือ (วัน) | J7: ใบ | K7: ชิ้น | L7: ใบ | M7: ชิ้น | N7: เกณฑ์ | O7: คงเหลือวันที่ส่งได้
A8: 1 | B8: NEWยูมิยูมิ มิลค์เค้ก 55กรัม | C8: =SUMIF(Data!E:E,B8,Data!F:F) -> 42 | E8: ชิ้น | H8: =+G8-$D$6 -> 0 | J8: =ROUNDDOWN((D8/C8),0) -> 0 | K8: =SUMIF(Data!E:E,'มหาชัย(2)'!B8,Data!F:F)*J8 -> 0 | L8: =ROUNDUP((M8/C8),0) -> 0 | M8: =D8-K8 -> 0 | N8: =INDEX(Data!C:C,MATCH(F4,Data!B:B,0)) -> 60 | O8: =H8-N8 -> -60
A9: 2 | B9: ใหม่ !! ยูมิยูมิ เค้กไข่ชีส 78กรัม | C9: =SUMIF(Data!E:E,B9,Data!F:F) -> 36 | E9: ชิ้น | H9: =+G9-$D$6 -> 0 | J9: =ROUNDDOWN((D9/C9),0) -> 0 | K9: =SUMIF(Data!E:E,'มหาชัย(2)'!B9,Data!F:F)*J9 -> 0 | L9: =ROUNDUP((M9/C9),0) -> 0 | M9: =D9-K9 -> 0 | N9: =INDEX(Data!C:C,MATCH(F5,Data!B:B,0)) -> #N/A | O9: =H9-N9 -> #N/A
A10: 3 | B10: ยูมิยูมิ เค้กอัลมอนด์ 75กรัม | C10: =SUMIF(Data!E:E,B10,Data!F:F) -> 42 | E10: ชิ้น | H10: =+G10-$D$6 -> 0 | J10: =ROUNDDOWN((D10/C10),0) -> 0 | K10: =SUMIF(Data!E:E,'มหาชัย(2)'!B10,Data!F:F)*J10 -> 0 | L10: =ROUNDUP((M10/C10),0) -> 0 | M10: =D10-K10 -> 0 | N10: =INDEX(Data!C:C,MATCH(F6,Data!B:B,0)) -> #N/A | O10: =H10-N10 -> #N/A
A11: 4 | B11: ยูมิยูมิ โรลช็อกโกแลตเค้ก 55กรัม | C11: =SUMIF(Data!E:E,B11,Data!F:F) -> 50 | E11: ชิ้น | H11: =+G11-$D$6 -> 0 | J11: =ROUNDDOWN((D11/C11),0) -> 0 | K11: =SUMIF(Data!E:E,'มหาชัย(2)'!B11,Data!F:F)*J11 -> 0 | L11: =ROUNDUP((M11/C11),0) -> 0 | M11: =D11-K11 -> 0 | N11: =INDEX(Data!C:C,MATCH(F7,Data!B:B,0)) -> #N/A | O11: =H11-N11 -> #N/A
A12: 5 | B12: ยูมิยูมิ มินิครีมเค้ก 40กรัม | C12: =SUMIF(Data!E:E,B12,Data!F:F) -> 81 | E12: ชิ้น | H12: =+G12-$D$6 -> 0 | J12: =ROUNDDOWN((D12/C12),0) -> 0 | K12: =SUMIF(Data!E:E,'มหาชัย(2)'!B12,Data!F:F)*J12 -> 0 | L12: =ROUNDUP((M12/C12),0) -> 0 | M12: =D12-K12 -> 0 | N12: =INDEX(Data!C:C,MATCH(F8,Data!B:B,0)) -> #N/A | O12: =H12-N12 -> #N/A
A13: 6 | B13: ยูมิยูมิ เค้กครีมสลัดไก่หยอง 75กรัม | C13: =SUMIF(Data!E:E,B13,Data!F:F) -> 42 | E13: ชิ้น | H13: =+G13-$D$6 -> 0 | J13: =ROUNDDOWN((D13/C13),0) -> 0 | K13: =SUMIF(Data!E:E,'มหาชัย(2)'!B13,Data!F:F)*J13 -> 0 | L13: =ROUNDUP((M13/C13),0) -> 0 | M13: =D13-K13 -> 0 | N13: =INDEX(Data!C:C,MATCH(F9,Data!B:B,0)) -> #N/A | O13: =H13-N13 -> #N/A
A14: 7 | B14: ยูมิยูมิ ชิสึเค้ก 70กรัม | C14: =SUMIF(Data!E:E,B14,Data!F:F) -> 32 | E14: ชิ้น | H14: =+G14-$D$6 -> 0 | J14: =ROUNDDOWN((D14/C14),0) -> 0 | K14: =SUMIF(Data!E:E,'มหาชัย(2)'!B14,Data!F:F)*J14 -> 0 | L14: =ROUNDUP((M14/C14),0) -> 0 | M14: =D14-K14 -> 0 | N14: =INDEX(Data!C:C,MATCH(F10,Data!B:B,0)) -> #N/A | O14: =H14-N14 -> #N/A
A15: 8 | B15: ยูมิยูมิ บลูเบอร์รี่เค้ก 52กรัม | C15: =SUMIF(Data!E:E,B15,Data!F:F) -> 70 | E15: ชิ้น | H15: =+G15-$D$6 -> 0 | J15: =ROUNDDOWN((D15/C15),0) -> 0 | K15: =SUMIF(Data!E:E,'มหาชัย(2)'!B15,Data!F:F)*J15 -> 0 | L15: =ROUNDUP((M15/C15),0) -> 0 | M15: =D15-K15 -> 0 | N15: =INDEX(Data!C:C,MATCH(F11,Data!B:B,0)) -> #N/A | O15: =H15-N15 -> #N/A
A16: 9 | B16: ยูมิยูมิ เค้กสาหร่ายไก่หยอง 75กรัม | C16: =SUMIF(Data!E:E,B16,Data!F:F) -> 45 | E16: ชิ้น | H16: =+G16-$D$6 -> 0 | J16: =ROUNDDOWN((D16/C16),0) -> 0 | K16: =SUMIF(Data!E:E,'มหาชัย(2)'!B16,Data!F:F)*J16 -> 0 | L16: =ROUNDUP((M16/C16),0) -> 0 | M16: =D16-K16 -> 0 | N16: =INDEX(Data!C:C,MATCH(F12,Data!B:B,0)) -> #N/A | O16: =H16-N16 -> #N/A
A17: 10 | B17: ยูมิยูมิ เค้กช็อกโกแลตเฮเซลนัท 75กรัม | C17: =SUMIF(Data!E:E,B17,Data!F:F) -> 48 | E17: ชิ้น | H17: =+G17-$D$6 -> 0 | J17: =ROUNDDOWN((D17/C17),0) -> 0 | K17: =SUMIF(Data!E:E,'มหาชัย(2)'!B17,Data!F:F)*J17 -> 0 | L17: =ROUNDUP((M17/C17),0) -> 0 | M17: =D17-K17 -> 0 | N17: =INDEX(Data!C:C,MATCH(F13,Data!B:B,0)) -> #N/A | O17: =H17-N17 -> #N/A
A18: 11 | B18: ยูมิยูมิ ชิฟฟอนชีสเค้ก 75กรัม | C18: =SUMIF(Data!E:E,B18,Data!F:F) -> 48 | E18: ชิ้น | H18: =+G18-$D$6 -> 0 | J18: =ROUNDDOWN((D18/C18),0) -> 0 | K18: =SUMIF(Data!E:E,'มหาชัย(2)'!B18,Data!F:F)*J18 -> 0 | L18: =ROUNDUP((M18/C18),0) -> 0 | M18: =D18-K18 -> 0 | N18: =INDEX(Data!C:C,MATCH(F14,Data!B:B,0)) -> #N/A | O18: =H18-N18 -> #N/A
A19: 12 | B19: วาฟเฟิลครีมโคโคนัทมิลค์ 62กรัม | C19: =SUMIF(Data!E:E,B19,Data!F:F) -> 60 | E19: ชิ้น | H19: =+G19-$D$6 -> 0 | J19: =ROUNDDOWN((D19/C19),0) -> 0 | K19: =SUMIF(Data!E:E,'มหาชัย(2)'!B19,Data!F:F)*J19 -> 0 | L19: =ROUNDUP((M19/C19),0) -> 0 | M19: =D19-K19 -> 0 | N19: =INDEX(Data!C:C,MATCH(F15,Data!B:B,0)) -> #N/A | O19: =H19-N19 -> #N/A
... A26: 19 | B26: ยูมิยูมิ มินิเค้กไส้ครีมกล้วยหอม 40กรัม | C26: =SUMIF(Data!E:E,B26,Data!F:F) -> 81 | E26: ชิ้น | H26: =+G26-$D$6 -> 0 | J26: =ROUNDDOWN((D26/C26),0) -> 0 | K26: =SUMIF(Data!E:E,'มหาชัย(2)'!B26,Data!F:F)*J26 -> 0 | L26: =ROUNDUP((M26/C26),0) -> 0 | M26: =D26-K26 -> 0 | N26: =INDEX(Data!C:C,MATCH(F22,Data!B:B,0)) -> #N/A | O26: =H26-N26 -> #N/A
A27: ยอดรวมสินค้า | J27: ตะกร้าเต็ม | K27: ตะกร้าเศษ | L27: รวมตะกร้า
J28: =SUM($J$8:$J$26) -> 0 | K28: =SUM($L$8:$L$26) -> 0 | L28: =SUM(J28:K28) -> 0
B30: ผู้รับผิดชอบ.......................................... ผู้ตรวจ (เช็คเกอร์)....................................... | G30: พนักงานขนส่ง..........................................
B31: วันที่จัดเสร็จ.......................................... วันที่จัดเสร็จ................................................ | G31: ทะเบียนขนส่ง.............................................
B32: เวลาที่จัดเสร็จ......................................... เวลาที่จัดเสร็จ............................................ | G32: เลขซีล/สี.....................................................

Sheet ขอนแก่น(3)
A1: บริษัท แวลู่พลัส รีเทล จำกัด | G1: รถคันที่ : | H1: 1/1
G2: วันที่ :
A3: ใบจัดสินค้า
A4: ลูกค้า | B4: บริษัท ซีพี ออลล์ จำกัด | D4: สถานที่จัดส่ง | F4: BDC.ขอนแก่น
A5: IV | D5: วันที่ส่ง | J5: คำวนตะกร้า
J6: ตะกร้าเต็ม | L6: ตะกร้าเศษ
A7: ลำดับ | B7: ชื่อสินค้า | C7: บรรจุ | D7: จำนวน | E7: หน่วย | F7: MFD | G7: BBF/EXP | H7: อายุคงเหลือ (วัน) | J7: ใบ | K7: ชิ้น | L7: ใบ | M7: ชิ้น | N7: เกณฑ์ | O7: คงเหลือวันที่ส่งได้
A8: 1 | B8: NEWยูมิยูมิ มิลค์เค้ก 55กรัม | C8: =SUMIF(Data!E:E,B8,Data!F:F) -> 42 | E8: ชิ้น | H8: =+G8-$D$6 -> 0 | J8: =ROUNDDOWN((D8/C8),0) -> 0 | K8: =SUMIF(Data!E:E,'มหาชัย(2)'!B8,Data!F:F)*J8 -> 0 | L8: =ROUNDUP((M8/C8),0) -> 0 | M8: =D8-K8 -> 0 | N8: =INDEX(Data!C:C,MATCH(F4,Data!B:B,0)) -> 60 | O8: =H8-N8 -> -60
A9: 2 | B9: ใหม่ !! ยูมิยูมิ เค้กไข่ชีส 78กรัม | C9: =SUMIF(Data!E:E,B9,Data!F:F) -> 36 | E9: ชิ้น | H9: =+G9-$D$6 -> 0 | J9: =ROUNDDOWN((D9/C9),0) -> 0 | K9: =SUMIF(Data!E:E,'มหาชัย(2)'!B9,Data!F:F)*J9 -> 0 | L9: =ROUNDUP((M9/C9),0) -> 0 | M9: =D9-K9 -> 0 | N9: =INDEX(Data!C:C,MATCH(F5,Data!B:B,0)) -> #N/A | O9: =H9-N9 -> #N/A
A10: 3 | B10: ยูมิยูมิ เค้กอัลมอนด์ 75กรัม | C10: =SUMIF(Data!E:E,B10,Data!F:F) -> 42 | E10: ชิ้น | H10: =+G10-$D$6 -> 0 | J10: =ROUNDDOWN((D10/C10),0) -> 0 | K10: =SUMIF(Data!E:E,'มหาชัย(2)'!B10,Data!F:F)*J10 -> 0 | L10: =ROUNDUP((M10/C10),0) -> 0 | M10: =D10-K10 -> 0 | N10: =INDEX(Data!C:C,MATCH(F6,Data!B:B,0)) -> #N/A | O10: =H10-N10 -> #N/A
A11: 4 | B11: ยูมิยูมิ โรลช็อกโกแลตเค้ก 55กรัม | C11: =SUMIF(Data!E:E,B11,Data!F:F) -> 50 | E11: ชิ้น | H11: =+G11-$D$6 -> 0 | J11: =ROUNDDOWN((D11/C11),0) -> 0 | K11: =SUMIF(Data!E:E,'มหาชัย(2)'!B11,Data!F:F)*J11 -> 0 | L11: =ROUNDUP((M11/C11),0) -> 0 | M11: =D11-K11 -> 0 | N11: =INDEX(Data!C:C,MATCH(F7,Data!B:B,0)) -> #N/A | O11: =H11-N11 -> #N/A
A12: 5 | B12: ยูมิยูมิ มินิครีมเค้ก 40กรัม | C12: =SUMIF(Data!E:E,B12,Data!F:F) -> 81 | E12: ชิ้น | H12: =+G12-$D$6 -> 0 | J12: =ROUNDDOWN((D12/C12),0) -> 0 | K12: =SUMIF(Data!E:E,'มหาชัย(2)'!B12,Data!F:F)*J12 -> 0 | L12: =ROUNDUP((M12/C12),0) -> 0 | M12: =D12-K12 -> 0 | N12: =INDEX(Data!C:C,MATCH(F8,Data!B:B,0)) -> #N/A | O12: =H12-N12 -> #N/A
A13: 6 | B13: ยูมิยูมิ เค้กครีมสลัดไก่หยอง 75กรัม | C13: =SUMIF(Data!E:E,B13,Data!F:F) -> 42 | E13: ชิ้น | H13: =+G13-$D$6 -> 0 | J13: =ROUNDDOWN((D13/C13),0) -> 0 | K13: =SUMIF(Data!E:E,'มหาชัย(2)'!B13,Data!F:F)*J13 -> 0 | L13: =ROUNDUP((M13/C13),0) -> 0 | M13: =D13-K13 -> 0 | N13: =INDEX(Data!C:C,MATCH(F9,Data!B:B,0)) -> #N/A | O13: =H13-N13 -> #N/A
A14: 7 | B14: ยูมิยูมิ ชิสึเค้ก 70กรัม | C14: =SUMIF(Data!E:E,B14,Data!F:F) -> 32 | E14: ชิ้น | H14: =+G14-$D$6 -> 0 | J14: =ROUNDDOWN((D14/C14),0) -> 0 | K14: =SUMIF(Data!E:E,'มหาชัย(2)'!B14,Data!F:F)*J14 -> 0 | L14: =ROUNDUP((M14/C14),0) -> 0 | M14: =D14-K14 -> 0 | N14: =INDEX(Data!C:C,MATCH(F10,Data!B:B,0)) -> #N/A | O14: =H14-N14 -> #N/A
A15: 8 | B15: ยูมิยูมิ บลูเบอร์รี่เค้ก 52กรัม | C15: =SUMIF(Data!E:E,B15,Data!F:F) -> 70 | E15: ชิ้น | H15: =+G15-$D$6 -> 0 | J15: =ROUNDDOWN((D15/C15),0) -> 0 | K15: =SUMIF(Data!E:E,'มหาชัย(2)'!B15,Data!F:F)*J15 -> 0 | L15: =ROUNDUP((M15/C15),0) -> 0 | M15: =D15-K15 -> 0 | N15: =INDEX(Data!C:C,MATCH(F11,Data!B:B,0)) -> #N/A | O15: =H15-N15 -> #N/A
A16: 9 | B16: ยูมิยูมิ เค้กสาหร่ายไก่หยอง 75กรัม | C16: =SUMIF(Data!E:E,B16,Data!F:F) -> 45 | E16: ชิ้น | H16: =+G16-$D$6 -> 0 | J16: =ROUNDDOWN((D16/C16),0) -> 0 | K16: =SUMIF(Data!E:E,'มหาชัย(2)'!B16,Data!F:F)*J16 -> 0 | L16: =ROUNDUP((M16/C16),0) -> 0 | M16: =D16-K16 -> 0 | N16: =INDEX(Data!C:C,MATCH(F12,Data!B:B,0)) -> #N/A | O16: =H16-N16 -> #N/A
A17: 10 | B17: ยูมิยูมิ เค้กช็อกโกแลตเฮเซลนัท 75กรัม | C17: =SUMIF(Data!E:E,B17,Data!F:F) -> 48 | E17: ชิ้น | H17: =+G17-$D$6 -> 0 | J17: =ROUNDDOWN((D17/C17),0) -> 0 | K17: =SUMIF(Data!E:E,'มหาชัย(2)'!B17,Data!F:F)*J17 -> 0 | L17: =ROUNDUP((M17/C17),0) -> 0 | M17: =D17-K17 -> 0 | N17: =INDEX(Data!C:C,MATCH(F13,Data!B:B,0)) -> #N/A | O17: =H17-N17 -> #N/A
A18: 11 | B18: ยูมิยูมิ ชิฟฟอนชีสเค้ก 75กรัม | C18: =SUMIF(Data!E:E,B18,Data!F:F) -> 48 | E18: ชิ้น | H18: =+G18-$D$6 -> 0 | J18: =ROUNDDOWN((D18/C18),0) -> 0 | K18: =SUMIF(Data!E:E,'มหาชัย(2)'!B18,Data!F:F)*J18 -> 0 | L18: =ROUNDUP((M18/C18),0) -> 0 | M18: =D18-K18 -> 0 | N18: =INDEX(Data!C:C,MATCH(F14,Data!B:B,0)) -> #N/A | O18: =H18-N18 -> #N/A
A19: 12 | B19: วาฟเฟิลครีมโคโคนัทมิลค์ 62กรัม | C19: =SUMIF(Data!E:E,B19,Data!F:F) -> 60 | E19: ชิ้น | H19: =+G19-$D$6 -> 0 | J19: =ROUNDDOWN((D19/C19),0) -> 0 | K19: =SUMIF(Data!E:E,'มหาชัย(2)'!B19,Data!F:F)*J19 -> 0 | L19: =ROUNDUP((M19/C19),0) -> 0 | M19: =D19-K19 -> 0 | N19: =INDEX(Data!C:C,MATCH(F15,Data!B:B,0)) -> #N/A | O19: =H19-N19 -> #N/A
... A26: 19 | B26: ยูมิยูมิ มินิเค้กไส้ครีมกล้วยหอม 40กรัม | C26: =SUMIF(Data!E:E,B26,Data!F:F) -> 81 | E26: ชิ้น | H26: =+G26-$D$6 -> 0 | J26: =ROUNDDOWN((D26/C26),0) -> 0 | K26: =SUMIF(Data!E:E,'มหาชัย(2)'!B26,Data!F:F)*J26 -> 0 | L26: =ROUNDUP((M26/C26),0) -> 0 | M26: =D26-K26 -> 0 | N26: =INDEX(Data!C:C,MATCH(F22,Data!B:B,0)) -> #N/A | O26: =H26-N26 -> #N/A
A27: ยอดรวมสินค้า | J27: ตะกร้าเต็ม | K27: ตะกร้าเศษ | L27: รวมตะกร้า
J28: =SUM($J$8:$J$26) -> 0 | K28: =SUM($L$8:$L$26) -> 0 | L28: =SUM(J28:K28) -> 0
B30: ผู้รับผิดชอบ.......................................... ผู้ตรวจ (เช็คเกอร์)....................................... | G30: พนักงานขนส่ง..........................................
B31: วันที่จัดเสร็จ.......................................... วันที่จัดเสร็จ................................................ | G31: ทะเบียนขนส่ง.............................................
B32: เวลาที่จัดเสร็จ......................................... เวลาที่จัดเสร็จ............................................ | G32: เลขซีล/สี.....................................................

Sheet ขอนแก่น(2)
A1: บริษัท แวลู่พลัส รีเทล จำกัด | G1: รถคันที่ : | H1: 1/1
G2: วันที่ :
A3: ใบจัดสินค้า
A4: ลูกค้า | B4: บริษัท ซีพี ออลล์ จำกัด | D4: สถานที่จัดส่ง | F4: BDC.ขอนแก่น
A5: IV | D5: วันที่ส่ง | J5: คำวนตะกร้า
J6: ตะกร้าเต็ม | L6: ตะกร้าเศษ
A7: ลำดับ | B7: ชื่อสินค้า | C7: บรรจุ | D7: จำนวน | E7: หน่วย | F7: MFD | G7: BBF/EXP | H7: อายุคงเหลือ (วัน) | J7: ใบ | K7: ชิ้น | L7: ใบ | M7: ชิ้น | N7: เกณฑ์ | O7: คงเหลือวันที่ส่งได้
A8: 1 | B8: NEWยูมิยูมิ มิลค์เค้ก 55กรัม | C8: =SUMIF(Data!E:E,B8,Data!F:F) -> 42 | E8: ชิ้น | H8: =+G8-$D$6 -> 0 | J8: =ROUNDDOWN((D8/C8),0) -> 0 | K8: =SUMIF(Data!E:E,'มหาชัย(2)'!B8,Data!F:F)*J8 -> 0 | L8: =ROUNDUP((M8/C8),0) -> 0 | M8: =D8-K8 -> 0 | N8: =INDEX(Data!C:C,MATCH(F4,Data!B:B,0)) -> 60 | O8: =H8-N8 -> -60
A9: 2 | B9: ใหม่ !! ยูมิยูมิ เค้กไข่ชีส 78กรัม | C9: =SUMIF(Data!E:E,B9,Data!F:F) -> 36 | E9: ชิ้น | H9: =+G9-$D$6 -> 0 | J9: =ROUNDDOWN((D9/C9),0) -> 0 | K9: =SUMIF(Data!E:E,'มหาชัย(2)'!B9,Data!F:F)*J9 -> 0 | L9: =ROUNDUP((M9/C9),0) -> 0 | M9: =D9-K9 -> 0 | N9: =INDEX(Data!C:C,MATCH(F5,Data!B:B,0)) -> #N/A | O9: =H9-N9 -> #N/A
A10: 3 | B10: ยูมิยูมิ เค้กอัลมอนด์ 75กรัม | C10: =SUMIF(Data!E:E,B10,Data!F:F) -> 42 | E10: ชิ้น | H10: =+G10-$D$6 -> 0 | J10: =ROUNDDOWN((D10/C10),0) -> 0 | K10: =SUMIF(Data!E:E,'มหาชัย(2)'!B10,Data!F:F)*J10 -> 0 | L10: =ROUNDUP((M10/C10),0) -> 0 | M10: =D10-K10 -> 0 | N10: =INDEX(Data!C:C,MATCH(F6,Data!B:B,0)) -> #N/A | O10: =H10-N10 -> #N/A
A11: 4 | B11: ยูมิยูมิ โรลช็อกโกแลตเค้ก 55กรัม | C11: =SUMIF(Data!E:E,B11,Data!F:F) -> 50 | E11: ชิ้น | H11: =+G11-$D$6 -> 0 | J11: =ROUNDDOWN((D11/C11),0) -> 0 | K11: =SUMIF(Data!E:E,'มหาชัย(2)'!B11,Data!F:F)*J11 -> 0 | L11: =ROUNDUP((M11/C11),0) -> 0 | M11: =D11-K11 -> 0 | N11: =INDEX(Data!C:C,MATCH(F7,Data!B:B,0)) -> #N/A | O11: =H11-N11 -> #N/A
A12: 5 | B12: ยูมิยูมิ มินิครีมเค้ก 40กรัม | C12: =SUMIF(Data!E:E,B12,Data!F:F) -> 81 | E12: ชิ้น | H12: =+G12-$D$6 -> 0 | J12: =ROUNDDOWN((D12/C12),0) -> 0 | K12: =SUMIF(Data!E:E,'มหาชัย(2)'!B12,Data!F:F)*J12 -> 0 | L12: =ROUNDUP((M12/C12),0) -> 0 | M12: =D12-K12 -> 0 | N12: =INDEX(Data!C:C,MATCH(F8,Data!B:B,0)) -> #N/A | O12: =H12-N12 -> #N/A
A13: 6 | B13: ยูมิยูมิ เค้กครีมสลัดไก่หยอง 75กรัม | C13: =SUMIF(Data!E:E,B13,Data!F:F) -> 42 | E13: ชิ้น | H13: =+G13-$D$6 -> 0 | J13: =ROUNDDOWN((D13/C13),0) -> 0 | K13: =SUMIF(Data!E:E,'มหาชัย(2)'!B13,Data!F:F)*J13 -> 0 | L13: =ROUNDUP((M13/C13),0) -> 0 | M13: =D13-K13 -> 0 | N13: =INDEX(Data!C:C,MATCH(F9,Data!B:B,0)) -> #N/A | O13: =H13-N13 -> #N/A
A14: 7 | B14: ยูมิยูมิ ชิสึเค้ก 70กรัม | C14: =SUMIF(Data!E:E,B14,Data!F:F) -> 32 | E14: ชิ้น | H14: =+G14-$D$6 -> 0 | J14: =ROUNDDOWN((D14/C14),0) -> 0 | K14: =SUMIF(Data!E:E,'มหาชัย(2)'!B14,Data!F:F)*J14 -> 0 | L14: =ROUNDUP((M14/C14),0) -> 0 | M14: =D14-K14 -> 0 | N14: =INDEX(Data!C:C,MATCH(F10,Data!B:B,0)) -> #N/A | O14: =H14-N14 -> #N/A
A15: 8 | B15: ยูมิยูมิ บลูเบอร์รี่เค้ก 52กรัม | C15: =SUMIF(Data!E:E,B15,Data!F:F) -> 70 | E15: ชิ้น | H15: =+G15-$D$6 -> 0 | J15: =ROUNDDOWN((D15/C15),0) -> 0 | K15: =SUMIF(Data!E:E,'มหาชัย(2)'!B15,Data!F:F)*J15 -> 0 | L15: =ROUNDUP((M15/C15),0) -> 0 | M15: =D15-K15 -> 0 | N15: =INDEX(Data!C:C,MATCH(F11,Data!B:B,0)) -> #N/A | O15: =H15-N15 -> #N/A
A16: 9 | B16: ยูมิยูมิ เค้กสาหร่ายไก่หยอง 75กรัม | C16: =SUMIF(Data!E:E,B16,Data!F:F) -> 45 | E16: ชิ้น | H16: =+G16-$D$6 -> 0 | J16: =ROUNDDOWN((D16/C16),0) -> 0 | K16: =SUMIF(Data!E:E,'มหาชัย(2)'!B16,Data!F:F)*J16 -> 0 | L16: =ROUNDUP((M16/C16),0) -> 0 | M16: =D16-K16 -> 0 | N16: =INDEX(Data!C:C,MATCH(F12,Data!B:B,0)) -> #N/A | O16: =H16-N16 -> #N/A
A17: 10 | B17: ยูมิยูมิ เค้กช็อกโกแลตเฮเซลนัท 75กรัม | C17: =SUMIF(Data!E:E,B17,Data!F:F) -> 48 | E17: ชิ้น | H17: =+G17-$D$6 -> 0 | J17: =ROUNDDOWN((D17/C17),0) -> 0 | K17: =SUMIF(Data!E:E,'มหาชัย(2)'!B17,Data!F:F)*J17 -> 0 | L17: =ROUNDUP((M17/C17),0) -> 0 | M17: =D17-K17 -> 0 | N17: =INDEX(Data!C:C,MATCH(F13,Data!B:B,0)) -> #N/A | O17: =H17-N17 -> #N/A
A18: 11 | B18: ยูมิยูมิ ชิฟฟอนชีสเค้ก 75กรัม | C18: =SUMIF(Data!E:E,B18,Data!F:F) -> 48 | E18: ชิ้น | H18: =+G18-$D$6 -> 0 | J18: =ROUNDDOWN((D18/C18),0) -> 0 | K18: =SUMIF(Data!E:E,'มหาชัย(2)'!B18,Data!F:F)*J18 -> 0 | L18: =ROUNDUP((M18/C18),0) -> 0 | M18: =D18-K18 -> 0 | N18: =INDEX(Data!C:C,MATCH(F14,Data!B:B,0)) -> #N/A | O18: =H18-N18 -> #N/A
A19: 12 | B19: วาฟเฟิลครีมโคโคนัทมิลค์ 62กรัม | C19: =SUMIF(Data!E:E,B19,Data!F:F) -> 60 | E19: ชิ้น | H19: =+G19-$D$6 -> 0 | J19: =ROUNDDOWN((D19/C19),0) -> 0 | K19: =SUMIF(Data!E:E,'มหาชัย(2)'!B19,Data!F:F)*J19 -> 0 | L19: =ROUNDUP((M19/C19),0) -> 0 | M19: =D19-K19 -> 0 | N19: =INDEX(Data!C:C,MATCH(F15,Data!B:B,0)) -> #N/A | O19: =H19-N19 -> #N/A
... A26: 19 | B26: ยูมิยูมิ มินิเค้กไส้ครีมกล้วยหอม 40กรัม | C26: =SUMIF(Data!E:E,B26,Data!F:F) -> 81 | E26: ชิ้น | H26: =+G26-$D$6 -> 0 | J26: =ROUNDDOWN((D26/C26),0) -> 0 | K26: =SUMIF(Data!E:E,'มหาชัย(2)'!B26,Data!F:F)*J26 -> 0 | L26: =ROUNDUP((M26/C26),0) -> 0 | M26: =D26-K26 -> 0 | N26: =INDEX(Data!C:C,MATCH(F22,Data!B:B,0)) -> #N/A | O26: =H26-N26 -> #N/A
A27: ยอดรวมสินค้า | J27: ตะกร้าเต็ม | K27: ตะกร้าเศษ | L27: รวมตะกร้า
J28: =SUM($J$8:$J$26) -> 0 | K28: =SUM($L$8:$L$26) -> 0 | L28: =SUM(J28:K28) -> 0
B30: ผู้รับผิดชอบ.......................................... ผู้ตรวจ (เช็คเกอร์)....................................... | G30: พนักงานขนส่ง..........................................
B31: วันที่จัดเสร็จ.......................................... วันที่จัดเสร็จ................................................ | G31: ทะเบียนขนส่ง.............................................
B32: เวลาที่จัดเสร็จ......................................... เวลาที่จัดเสร็จ............................................ | G32: เลขซีล/สี.....................................................

Sheet ขอนแก่น(1)
A1: บริษัท แวลู่พลัส รีเทล จำกัด | G1: รถคันที่ : | H1: 1/1
G2: วันที่ :
A3: ใบจัดสินค้า
A4: ลูกค้า | B4: บริษัท ซีพี ออลล์ จำกัด | D4: สถานที่จัดส่ง | F4: BDC.ขอนแก่น
A5: IV | D5: วันที่ส่ง | J5: คำวนตะกร้า
J6: ตะกร้าเต็ม | L6: ตะกร้าเศษ
A7: ลำดับ | B7: ชื่อสินค้า | C7: บรรจุ | D7: จำนวน | E7: หน่วย | F7: MFD | G7: BBF/EXP | H7: อายุคงเหลือ (วัน) | J7: ใบ | K7: ชิ้น | L7: ใบ | M7: ชิ้น | N7: เกณฑ์ | O7: คงเหลือวันที่ส่งได้
A8: 1 | B8: NEWยูมิยูมิ มิลค์เค้ก 55กรัม | C8: =SUMIF(Data!E:E,B8,Data!F:F) -> 42 | E8: ชิ้น | H8: =+G8-$D$6 -> 0 | J8: =ROUNDDOWN((D8/C8),0) -> 0 | K8: =SUMIF(Data!E:E,'มหาชัย(2)'!B8,Data!F:F)*J8 -> 0 | L8: =ROUNDUP((M8/C8),0) -> 0 | M8: =D8-K8 -> 0 | N8: =INDEX(Data!C:C,MATCH(F4,Data!B:B,0)) -> 60 | O8: =H8-N8 -> -60
A9: 2 | B9: ใหม่ !! ยูมิยูมิ เค้กไข่ชีส 78กรัม | C9: =SUMIF(Data!E:E,B9,Data!F:F) -> 36 | E9: ชิ้น | H9: =+G9-$D$6 -> 0 | J9: =ROUNDDOWN((D9/C9),0) -> 0 | K9: =SUMIF(Data!E:E,'มหาชัย(2)'!B9,Data!F:F)*J9 -> 0 | L9: =ROUNDUP((M9/C9),0) -> 0 | M9: =D9-K9 -> 0 | N9: =INDEX(Data!C:C,MATCH(F5,Data!B:B,0)) -> #N/A | O9: =H9-N9 -> #N/A
A10: 3 | B10: ยูมิยูมิ เค้กอัลมอนด์ 75กรัม | C10: =SUMIF(Data!E:E,B10,Data!F:F) -> 42 | E10: ชิ้น | H10: =+G10-$D$6 -> 0 | J10: =ROUNDDOWN((D10/C10),0) -> 0 | K10: =SUMIF(Data!E:E,'มหาชัย(2)'!B10,Data!F:F)*J10 -> 0 | L10: =ROUNDUP((M10/C10),0) -> 0 | M10: =D10-K10 -> 0 | N10: =INDEX(Data!C:C,MATCH(F6,Data!B:B,0)) -> #N/A | O10: =H10-N10 -> #N/A
A11: 4 | B11: ยูมิยูมิ โรลช็อกโกแลตเค้ก 55กรัม | C11: =SUMIF(Data!E:E,B11,Data!F:F) -> 50 | E11: ชิ้น | H11: =+G11-$D$6 -> 0 | J11: =ROUNDDOWN((D11/C11),0) -> 0 | K11: =SUMIF(Data!E:E,'มหาชัย(2)'!B11,Data!F:F)*J11 -> 0 | L11: =ROUNDUP((M11/C11),0) -> 0 | M11: =D11-K11 -> 0 | N11: =INDEX(Data!C:C,MATCH(F7,Data!B:B,0)) -> #N/A | O11: =H11-N11 -> #N/A
A12: 5 | B12: ยูมิยูมิ มินิครีมเค้ก 40กรัม | C12: =SUMIF(Data!E:E,B12,Data!F:F) -> 81 | E12: ชิ้น | H12: =+G12-$D$6 -> 0 | J12: =ROUNDDOWN((D12/C12),0) -> 0 | K12: =SUMIF(Data!E:E,'มหาชัย(2)'!B12,Data!F:F)*J12 -> 0 | L12: =ROUNDUP((M12/C12),0) -> 0 | M12: =D12-K12 -> 0 | N12: =INDEX(Data!C:C,MATCH(F8,Data!B:B,0)) -> #N/A | O12: =H12-N12 -> #N/A
A13: 6 | B13: ยูมิยูมิ เค้กครีมสลัดไก่หยอง 75กรัม | C13: =SUMIF(Data!E:E,B13,Data!F:F) -> 42 | E13: ชิ้น | H13: =+G13-$D$6 -> 0 | J13: =ROUNDDOWN((D13/C13),0) -> 0 | K13: =SUMIF(Data!E:E,'มหาชัย(2)'!B13,Data!F:F)*J13 -> 0 | L13: =ROUNDUP((M13/C13),0) -> 0 | M13: =D13-K13 -> 0 | N13: =INDEX(Data!C:C,MATCH(F9,Data!B:B,0)) -> #N/A | O13: =H13-N13 -> #N/A
A14: 7 | B14: ยูมิยูมิ ชิสึเค้ก 70กรัม | C14: =SUMIF(Data!E:E,B14,Data!F:F) -> 32 | E14: ชิ้น | H14: =+G14-$D$6 -> 0 | J14: =ROUNDDOWN((D14/C14),0) -> 0 | K14: =SUMIF(Data!E:E,'มหาชัย(2)'!B14,Data!F:F)*J14 -> 0 | L14: =ROUNDUP((M14/C14),0) -> 0 | M14: =D14-K14 -> 0 | N14: =INDEX(Data!C:C,MATCH(F10,Data!B:B,0)) -> #N/A | O14: =H14-N14 -> #N/A
A15: 8 | B15: ยูมิยูมิ บลูเบอร์รี่เค้ก 52กรัม | C15: =SUMIF(Data!E:E,B15,Data!F:F) -> 70 | E15: ชิ้น | H15: =+G15-$D$6 -> 0 | J15: =ROUNDDOWN((D15/C15),0) -> 0 | K15: =SUMIF(Data!E:E,'มหาชัย(2)'!B15,Data!F:F)*J15 -> 0 | L15: =ROUNDUP((M15/C15),0) -> 0 | M15: =D15-K15 -> 0 | N15: =INDEX(Data!C:C,MATCH(F11,Data!B:B,0)) -> #N/A | O15: =H15-N15 -> #N/A
A16: 9 | B16: ยูมิยูมิ เค้กสาหร่ายไก่หยอง 75กรัม | C16: =SUMIF(Data!E:E,B16,Data!F:F) -> 45 | E16: ชิ้น | H16: =+G16-$D$6 -> 0 | J16: =ROUNDDOWN((D16/C16),0) -> 0 | K16: =SUMIF(Data!E:E,'มหาชัย(2)'!B16,Data!F:F)*J16 -> 0 | L16: =ROUNDUP((M16/C16),0) -> 0 | M16: =D16-K16 -> 0 | N16: =INDEX(Data!C:C,MATCH(F12,Data!B:B,0)) -> #N/A | O16: =H16-N16 -> #N/A
A17: 10 | B17: ยูมิยูมิ เค้กช็อกโกแลตเฮเซลนัท 75กรัม | C17: =SUMIF(Data!E:E,B17,Data!F:F) -> 48 | E17: ชิ้น | H17: =+G17-$D$6 -> 0 | J17: =ROUNDDOWN((D17/C17),0) -> 0 | K17: =SUMIF(Data!E:E,'มหาชัย(2)'!B17,Data!F:F)*J17 -> 0 | L17: =ROUNDUP((M17/C17),0) -> 0 | M17: =D17-K17 -> 0 | N17: =INDEX(Data!C:C,MATCH(F13,Data!B:B,0)) -> #N/A | O17: =H17-N17 -> #N/A
A18: 11 | B18: ยูมิยูมิ ชิฟฟอนชีสเค้ก 75กรัม | C18: =SUMIF(Data!E:E,B18,Data!F:F) -> 48 | E18: ชิ้น | H18: =+G18-$D$6 -> 0 | J18: =ROUNDDOWN((D18/C18),0) -> 0 | K18: =SUMIF(Data!E:E,'มหาชัย(2)'!B18,Data!F:F)*J18 -> 0 | L18: =ROUNDUP((M18/C18),0) -> 0 | M18: =D18-K18 -> 0 | N18: =INDEX(Data!C:C,MATCH(F14,Data!B:B,0)) -> #N/A | O18: =H18-N18 -> #N/A
A19: 12 | B19: วาฟเฟิลครีมโคโคนัทมิลค์ 62กรัม | C19: =SUMIF(Data!E:E,B19,Data!F:F) -> 60 | E19: ชิ้น | H19: =+G19-$D$6 -> 0 | J19: =ROUNDDOWN((D19/C19),0) -> 0 | K19: =SUMIF(Data!E:E,'มหาชัย(2)'!B19,Data!F:F)*J19 -> 0 | L19: =ROUNDUP((M19/C19),0) -> 0 | M19: =D19-K19 -> 0 | N19: =INDEX(Data!C:C,MATCH(F15,Data!B:B,0)) -> #N/A | O19: =H19-N19 -> #N/A
... A26: 19 | B26: ยูมิยูมิ มินิเค้กไส้ครีมกล้วยหอม 40กรัม | C26: =SUMIF(Data!E:E,B26,Data!F:F) -> 81 | E26: ชิ้น | H26: =+G26-$D$6 -> 0 | J26: =ROUNDDOWN((D26/C26),0) -> 0 | K26: =SUMIF(Data!E:E,'มหาชัย(2)'!B26,Data!F:F)*J26 -> 0 | L26: =ROUNDUP((M26/C26),0) -> 0 | M26: =D26-K26 -> 0 | N26: =INDEX(Data!C:C,MATCH(F22,Data!B:B,0)) -> #N/A | O26: =H26-N26 -> #N/A
A27: ยอดรวมสินค้า | J27: ตะกร้าเต็ม | K27: ตะกร้าเศษ | L27: รวมตะกร้า
J28: =SUM($J$8:$J$26) -> 0 | K28: =SUM($L$8:$L$26) -> 0 | L28: =SUM(J28:K28) -> 0
B30: ผู้รับผิดชอบ.......................................... ผู้ตรวจ (เช็คเกอร์)....................................... | G30: พนักงานขนส่ง..........................................
B31: วันที่จัดเสร็จ.......................................... วันที่จัดเสร็จ................................................ | G31: ทะเบียนขนส่ง.............................................
B32: เวลาที่จัดเสร็จ......................................... เวลาที่จัดเสร็จ............................................ | G32: เลขซีล/สี.....................................................

Sheet หาดใหญ่(1)
A1: บริษัท แวลู่พลัส รีเทล จำกัด | G1: รถคันที่ : | H1: 1/1
G2: วันที่ :
A3: ใบจัดสินค้า
A4: ลูกค้า | B4: บริษัท ซีพี ออลล์ จำกัด | D4: สถานที่จัดส่ง | F4: BDC.หาดใหญ่
A5: IV | D5: วันที่ส่ง | J5: คำวนตะกร้า
J6: ตะกร้าเต็ม | L6: ตะกร้าเศษ
A7: ลำดับ | B7: ชื่อสินค้า | C7: บรรจุ | D7: จำนวน | E7: หน่วย | F7: MFD | G7: BBF/EXP | H7: อายุคงเหลือ (วัน) | J7: ใบ | K7: ชิ้น | L7: ใบ | M7: ชิ้น | N7: เกณฑ์ | O7: คงเหลือวันที่ส่งได้
A8: 1 | B8: NEWยูมิยูมิ มิลค์เค้ก 55กรัม | C8: =SUMIF(Data!E:E,B8,Data!F:F) -> 42 | E8: ชิ้น | H8: =+G8-$D$6 -> 0 | J8: =ROUNDDOWN((D8/C8),0) -> 0 | K8: =SUMIF(Data!E:E,'มหาชัย(2)'!B8,Data!F:F)*J8 -> 0 | L8: =ROUNDUP((M8/C8),0) -> 0 | M8: =D8-K8 -> 0 | N8: =INDEX(Data!C:C,MATCH(F4,Data!B:B,0)) -> 60 | O8: =H8-N8 -> -60
A9: 2 | B9: ใหม่ !! ยูมิยูมิ เค้กไข่ชีส 78กรัม | C9: =SUMIF(Data!E:E,B9,Data!F:F) -> 36 | E9: ชิ้น | H9: =+G9-$D$6 -> 0 | J9: =ROUNDDOWN((D9/C9),0) -> 0 | K9: =SUMIF(Data!E:E,'มหาชัย(2)'!B9,Data!F:F)*J9 -> 0 | L9: =ROUNDUP((M9/C9),0) -> 0 | M9: =D9-K9 -> 0 | N9: =INDEX(Data!C:C,MATCH(F5,Data!B:B,0)) -> #N/A | O9: =H9-N9 -> #N/A
A10: 3 | B10: ยูมิยูมิ เค้กอัลมอนด์ 75กรัม | C10: =SUMIF(Data!E:E,B10,Data!F:F) -> 42 | E10: ชิ้น | H10: =+G10-$D$6 -> 0 | J10: =ROUNDDOWN((D10/C10),0) -> 0 | K10: =SUMIF(Data!E:E,'มหาชัย(2)'!B10,Data!F:F)*J10 -> 0 | L10: =ROUNDUP((M10/C10),0) -> 0 | M10: =D10-K10 -> 0 | N10: =INDEX(Data!C:C,MATCH(F6,Data!B:B,0)) -> #N/A | O10: =H10-N10 -> #N/A
A11: 4 | B11: ยูมิยูมิ โรลช็อกโกแลตเค้ก 55กรัม | C11: =SUMIF(Data!E:E,B11,Data!F:F) -> 50 | E11: ชิ้น | H11: =+G11-$D$6 -> 0 | J11: =ROUNDDOWN((D11/C11),0) -> 0 | K11: =SUMIF(Data!E:E,'มหาชัย(2)'!B11,Data!F:F)*J11 -> 0 | L11: =ROUNDUP((M11/C11),0) -> 0 | M11: =D11-K11 -> 0 | N11: =INDEX(Data!C:C,MATCH(F7,Data!B:B,0)) -> #N/A | O11: =H11-N11 -> #N/A
A12: 5 | B12: ยูมิยูมิ มินิครีมเค้ก 40กรัม | C12: =SUMIF(Data!E:E,B12,Data!F:F) -> 81 | E12: ชิ้น | H12: =+G12-$D$6 -> 0 | J12: =ROUNDDOWN((D12/C12),0) -> 0 | K12: =SUMIF(Data!E:E,'มหาชัย(2)'!B12,Data!F:F)*J12 -> 0 | L12: =ROUNDUP((M12/C12),0) -> 0 | M12: =D12-K12 -> 0 | N12: =INDEX(Data!C:C,MATCH(F8,Data!B:B,0)) -> #N/A | O12: =H12-N12 -> #N/A
A13: 6 | B13: ยูมิยูมิ เค้กครีมสลัดไก่หยอง 75กรัม | C13: =SUMIF(Data!E:E,B13,Data!F:F) -> 42 | E13: ชิ้น | H13: =+G13-$D$6 -> 0 | J13: =ROUNDDOWN((D13/C13),0) -> 0 | K13: =SUMIF(Data!E:E,'มหาชัย(2)'!B13,Data!F:F)*J13 -> 0 | L13: =ROUNDUP((M13/C13),0) -> 0 | M13: =D13-K13 -> 0 | N13: =INDEX(Data!C:C,MATCH(F9,Data!B:B,0)) -> #N/A | O13: =H13-N13 -> #N/A
A14: 7 | B14: ยูมิยูมิ ชิสึเค้ก 70กรัม | C14: =SUMIF(Data!E:E,B14,Data!F:F) -> 32 | E14: ชิ้น | H14: =+G14-$D$6 -> 0 | J14: =ROUNDDOWN((D14/C14),0) -> 0 | K14: =SUMIF(Data!E:E,'มหาชัย(2)'!B14,Data!F:F)*J14 -> 0 | L14: =ROUNDUP((M14/C14),0) -> 0 | M14: =D14-K14 -> 0 | N14: =INDEX(Data!C:C,MATCH(F10,Data!B:B,0)) -> #N/A | O14: =H14-N14 -> #N/A
A15: 8 | B15: ยูมิยูมิ บลูเบอร์รี่เค้ก 52กรัม | C15: =SUMIF(Data!E:E,B15,Data!F:F) -> 70 | E15: ชิ้น | H15: =+G15-$D$6 -> 0 | J15: =ROUNDDOWN((D15/C15),0) -> 0 | K15: =SUMIF(Data!E:E,'มหาชัย(2)'!B15,Data!F:F)*J15 -> 0 | L15: =ROUNDUP((M15/C15),0) -> 0 | M15: =D15-K15 -> 0 | N15: =INDEX(Data!C:C,MATCH(F11,Data!B:B,0)) -> #N/A | O15: =H15-N15 -> #N/A
A16: 9 | B16: ยูมิยูมิ เค้กสาหร่ายไก่หยอง 75กรัม | C16: =SUMIF(Data!E:E,B16,Data!F:F) -> 45 | E16: ชิ้น | H16: =+G16-$D$6 -> 0 | J16: =ROUNDDOWN((D16/C16),0) -> 0 | K16: =SUMIF(Data!E:E,'มหาชัย(2)'!B16,Data!F:F)*J16 -> 0 | L16: =ROUNDUP((M16/C16),0) -> 0 | M16: =D16-K16 -> 0 | N16: =INDEX(Data!C:C,MATCH(F12,Data!B:B,0)) -> #N/A | O16: =H16-N16 -> #N/A
A17: 10 | B17: ยูมิยูมิ เค้กช็อกโกแลตเฮเซลนัท 75กรัม | C17: =SUMIF(Data!E:E,B17,Data!F:F) -> 48 | E17: ชิ้น | H17: =+G17-$D$6 -> 0 | J17: =ROUNDDOWN((D17/C17),0) -> 0 | K17: =SUMIF(Data!E:E,'มหาชัย(2)'!B17,Data!F:F)*J17 -> 0 | L17: =ROUNDUP((M17/C17),0) -> 0 | M17: =D17-K17 -> 0 | N17: =INDEX(Data!C:C,MATCH(F13,Data!B:B,0)) -> #N/A | O17: =H17-N17 -> #N/A
A18: 11 | B18: ยูมิยูมิ ชิฟฟอนชีสเค้ก 75กรัม | C18: =SUMIF(Data!E:E,B18,Data!F:F) -> 48 | E18: ชิ้น | H18: =+G18-$D$6 -> 0 | J18: =ROUNDDOWN((D18/C18),0) -> 0 | K18: =SUMIF(Data!E:E,'มหาชัย(2)'!B18,Data!F:F)*J18 -> 0 | L18: =ROUNDUP((M18/C18),0) -> 0 | M18: =D18-K18 -> 0 | N18: =INDEX(Data!C:C,MATCH(F14,Data!B:B,0)) -> #N/A | O18: =H18-N18 -> #N/A
A19: 12 | B19: วาฟเฟิลครีมโคโคนัทมิลค์ 62กรัม | C19: =SUMIF(Data!E:E,B19,Data!F:F) -> 60 | E19: ชิ้น | H19: =+G19-$D$6 -> 0 | J19: =ROUNDDOWN((D19/C19),0) -> 0 | K19: =SUMIF(Data!E:E,'มหาชัย(2)'!B19,Data!F:F)*J19 -> 0 | L19: =ROUNDUP((M19/C19),0) -> 0 | M19: =D19-K19 -> 0 | N19: =INDEX(Data!C:C,MATCH(F15,Data!B:B,0)) -> #N/A | O19: =H19-N19 -> #N/A
... A26: 19 | B26: ยูมิยูมิ มินิเค้กไส้ครีมกล้วยหอม 40กรัม | C26: =SUMIF(Data!E:E,B26,Data!F:F) -> 81 | E26: ชิ้น | H26: =+G26-$D$6 -> 0 | J26: =ROUNDDOWN((D26/C26),0) -> 0 | K26: =SUMIF(Data!E:E,'มหาชัย(2)'!B26,Data!F:F)*J26 -> 0 | L26: =ROUNDUP((M26/C26),0) -> 0 | M26: =D26-K26 -> 0 | N26: =INDEX(Data!C:C,MATCH(F22,Data!B:B,0)) -> #N/A | O26: =H26-N26 -> #N/A
A27: ยอดรวมสินค้า | J27: ตะกร้าเต็ม | K27: ตะกร้าเศษ | L27: รวมตะกร้า
J28: =SUM($J$8:$J$26) -> 0 | K28: =SUM($L$8:$L$26) -> 0 | L28: =SUM(J28:K28) -> 0
B30: ผู้รับผิดชอบ.......................................... ผู้ตรวจ (เช็คเกอร์)....................................... | G30: พนักงานขนส่ง.......................................... | K30: ยอดตระกร้ารวม | L30: =SUM('หาดใหญ่(1):สุราษฎร์ธานี(1)'!L28) -> 0
B31: วันที่จัดเสร็จ.......................................... วันที่จัดเสร็จ................................................ | G31: ทะเบียนขนส่ง............................................. | K31: ใช้รถ | L31: =L30/200 -> 0
B32: เวลาที่จัดเสร็จ......................................... เวลาที่จัดเสร็จ............................................ | G32: เลขซีล/สี.....................................................

Sheet สุราษฎร์ธานี(2)
A1: บริษัท แวลู่พลัส รีเทล จำกัด | G1: รถคันที่ : | H1: 1/1
G2: วันที่ :
A3: ใบจัดสินค้า
A4: ลูกค้า | B4: บริษัท ซีพี ออลล์ จำกัด | D4: สถานที่จัดส่ง | F4: BDC.สุราษฎร์
A5: IV | D5: วันที่ส่ง | J5: คำวนตะกร้า
J6: ตะกร้าเต็ม | L6: ตะกร้าเศษ
A7: ลำดับ | B7: ชื่อสินค้า | C7: บรรจุ | D7: จำนวน | E7: หน่วย | F7: MFD | G7: BBF/EXP | H7: อายุคงเหลือ (วัน) | J7: ใบ | K7: ชิ้น | L7: ใบ | M7: ชิ้น | N7: เกณฑ์ | O7: คงเหลือวันที่ส่งได้
A8: 1 | B8: NEWยูมิยูมิ มิลค์เค้ก 55กรัม | C8: =SUMIF(Data!E:E,B8,Data!F:F) -> 42 | E8: ชิ้น | H8: =+G8-$D$6 -> 0 | J8: =ROUNDDOWN((D8/C8),0) -> 0 | K8: =SUMIF(Data!E:E,'มหาชัย(2)'!B8,Data!F:F)*J8 -> 0 | L8: =ROUNDUP((M8/C8),0) -> 0 | M8: =D8-K8 -> 0 | N8: =INDEX(Data!C:C,MATCH(F4,Data!B:B,0)) -> 60 | O8: =H8-N8 -> -60
A9: 2 | B9: ใหม่ !! ยูมิยูมิ เค้กไข่ชีส 78กรัม | C9: =SUMIF(Data!E:E,B9,Data!F:F) -> 36 | E9: ชิ้น | H9: =+G9-$D$6 -> 0 | J9: =ROUNDDOWN((D9/C9),0) -> 0 | K9: =SUMIF(Data!E:E,'มหาชัย(2)'!B9,Data!F:F)*J9 -> 0 | L9: =ROUNDUP((M9/C9),0) -> 0 | M9: =D9-K9 -> 0 | N9: =INDEX(Data!C:C,MATCH(F5,Data!B:B,0)) -> #N/A | O9: =H9-N9 -> #N/A
A10: 3 | B10: ยูมิยูมิ เค้กอัลมอนด์ 75กรัม | C10: =SUMIF(Data!E:E,B10,Data!F:F) -> 42 | E10: ชิ้น | H10: =+G10-$D$6 -> 0 | J10: =ROUNDDOWN((D10/C10),0) -> 0 | K10: =SUMIF(Data!E:E,'มหาชัย(2)'!B10,Data!F:F)*J10 -> 0 | L10: =ROUNDUP((M10/C10),0) -> 0 | M10: =D10-K10 -> 0 | N10: =INDEX(Data!C:C,MATCH(F6,Data!B:B,0)) -> #N/A | O10: =H10-N10 -> #N/A
A11: 4 | B11: ยูมิยูมิ โรลช็อกโกแลตเค้ก 55กรัม | C11: =SUMIF(Data!E:E,B11,Data!F:F) -> 50 | E11: ชิ้น | H11: =+G11-$D$6 -> 0 | J11: =ROUNDDOWN((D11/C11),0) -> 0 | K11: =SUMIF(Data!E:E,'มหาชัย(2)'!B11,Data!F:F)*J11 -> 0 | L11: =ROUNDUP((M11/C11),0) -> 0 | M11: =D11-K11 -> 0 | N11: =INDEX(Data!C:C,MATCH(F7,Data!B:B,0)) -> #N/A | O11: =H11-N11 -> #N/A
A12: 5 | B12: ยูมิยูมิ มินิครีมเค้ก 40กรัม | C12: =SUMIF(Data!E:E,B12,Data!F:F) -> 81 | E12: ชิ้น | H12: =+G12-$D$6 -> 0 | J12: =ROUNDDOWN((D12/C12),0) -> 0 | K12: =SUMIF(Data!E:E,'มหาชัย(2)'!B12,Data!F:F)*J12 -> 0 | L12: =ROUNDUP((M12/C12),0) -> 0 | M12: =D12-K12 -> 0 | N12: =INDEX(Data!C:C,MATCH(F8,Data!B:B,0)) -> #N/A | O12: =H12-N12 -> #N/A
A13: 6 | B13: ยูมิยูมิ เค้กครีมสลัดไก่หยอง 75กรัม | C13: =SUMIF(Data!E:E,B13,Data!F:F) -> 42 | E13: ชิ้น | H13: =+G13-$D$6 -> 0 | J13: =ROUNDDOWN((D13/C13),0) -> 0 | K13: =SUMIF(Data!E:E,'มหาชัย(2)'!B13,Data!F:F)*J13 -> 0 | L13: =ROUNDUP((M13/C13),0) -> 0 | M13: =D13-K13 -> 0 | N13: =INDEX(Data!C:C,MATCH(F9,Data!B:B,0)) -> #N/A | O13: =H13-N13 -> #N/A
A14: 7 | B14: ยูมิยูมิ ชิสึเค้ก 70กรัม | C14: =SUMIF(Data!E:E,B14,Data!F:F) -> 32 | E14: ชิ้น | H14: =+G14-$D$6 -> 0 | J14: =ROUNDDOWN((D14/C14),0) -> 0 | K14: =SUMIF(Data!E:E,'มหาชัย(2)'!B14,Data!F:F)*J14 -> 0 | L14: =ROUNDUP((M14/C14),0) -> 0 | M14: =D14-K14 -> 0 | N14: =INDEX(Data!C:C,MATCH(F10,Data!B:B,0)) -> #N/A | O14: =H14-N14 -> #N/A
